Workbook

Sheet Sheet2
B2: INCOME
C3: Sales
C4: Week 1 | D4: ='PL-WM'!E4
C5: Week 2 | D5: ='PL-WM'!E5
C6: Week 3 | D6: ='PL-WM'!E6
C7: Week 4 | D7: ='PL-WM'!E7
C8: Week 5 | D8: ='PL-WM'!E8
C9: Total Sales | E9: =SUM(D4:D8)
C11: Gross Profit
C12: Week 1 | D12: ='PL-WM'!M4
C13: Week 2 | D13: ='PL-WM'!M5
C14: Week 3 | D14: ='PL-WM'!M6
C15: Week 4 | D15: ='PL-WM'!M7
C16: Week 5 | D16: ='PL-WM'!M8
C17: Total Gross Profit | E17: =SUM(D12:D16)
C19: Cost of Goods Sold/Purchase
C20: Week 1 | D20: ='PL-WM'!O4
C21: Week 2 | D21: ='PL-WM'!O5
C22: Week 3 | D22: ='PL-WM'!O6
C23: Week 4 | D23: ='PL-WM'!O7
C24: Week 5 | D24: ='PL-WM'!O8
C25: Total COGS | E25: =SUM(D20:D24)
C27: Net Profit
C28: Week 1 | D28: ='PL-WM'!W4
C29: Week 2 | D29: ='PL-WM'!W5
C30: Week 3 | D30: ='PL-WM'!W6
C31: Week 4 | D31: ='PL-WM'!W7
C32: Week 5 | D32: ='PL-WM'!W8
C33: Total Net Profit | E33: =SUM(D28:D32)
B36: EXPENSE
C37: Rent | D37: ='PL-WM'!Y9
C38: Payroll Expense | D38: ='PL-WM'!Z9
C39: Utilities- Electric | D39: ='PL-WM'!AA9
C40: Utilities-Water/Sewer | D40: ='PL-WM'!AB9
C41: Gas | D41: ='PL-WM'!AC9
C42: Insurance | D42: ='PL-WM'!AD9
C43: Repairs & Maintenance | D43: ='PL-WM'!AE9
C44: Aapa | D44: ='PL-WM'!AF9
C45: Help | D45: ='PL-WM'!AG9
C46: Bookkeeping | D46: ='PL-WM'!AH9
...

Sheet PL-WM
C2: SALES | G2: ITEMIZED PROFIT | O2: COGS | Q2: INCOME | Y2: EXPENSES
B3: WEEK | C3: INSIDE SALES | D3: PHONE CARDS SALES | E3: TOTAL NET SALES | G3: Grocery [30%] | H3: Lottery Sales | I3: Lottery [5%] | J3: Phone Cards | K3: Other Sales | L3: Others | M3: TOTAL GROSS PROFIT | O3: Total Purchase | Q3: Gross Profit | R3: ATM | S3: Other Rebate [LS/GM/CIG.] | T3: Total Expenses | U3: Profit | V3: Pullout | W3: Net Profit | Y3: Rent | Z3: Employee Salary | AA3: Utilities-Electric | AB3: Utilities-Water/Sewer | AC3: Gas | AD3: Insurance | AE3: Repairs & Maintenance | AF3: Aapa | AG3: Help | AH3: Bookeeping | AI3: Others | AJ3: Total Expenses | AL3: NET INCOME
B4: WEEK 1 | C4: ='S-Detail'!F13 | E4: =C4+D4 | G4: =E4*30% | I4: =H4*5% | J4: =D4*15% | L4: =K4*16% | M4: =SUM(G4:L4) | Q4: =M4 | T4: =AJ4 | U4: =Q4 | AJ4: =SUM(Y4:AI4) | AL4: =W4-AJ4
B5: WEEK 2 | C5: ='S-Detail'!F22 | E5: =C5+D5 | G5: =E5*30% | I5: =H5*5% | J5: =D5*15% | L5: =K5*16% | M5: =SUM(G5:L5) | Q5: =M5 | T5: =AJ5 | U5: =Q5 | AJ5: =SUM(Y5:AI5) | AL5: =W5-AJ5
B6: WEEK 3 | C6: ='S-Detail'!F31 | E6: =C6+D6 | G6: =E6*30% | I6: =H6*5% | J6: =D6*15% | L6: =K6*16% | M6: =SUM(G6:L6) | Q6: =M6 | T6: =AJ6 | U6: =Q6 | AJ6: =SUM(Y6:AI6) | AL6: =W6-AJ6
B7: WEEK 4 | C7: ='S-Detail'!F40 | E7: =C7+D7 | G7: =E7*30% | I7: =H7*5% | J7: =D7*15% | L7: =K7*16% | M7: =SUM(G7:L7) | Q7: =M7 | T7: =AJ7 | U7: =Q7 | AJ7: =SUM(Y7:AI7) | AL7: =W7-AJ7
B8: WEEK 5 | C8: ='S-Detail'!F45 | E8: =C8+D8 | G8: =E8*30% | I8: =H8*5% | J8: =D8*15% | L8: =K8*16% | M8: =SUM(G8:L8) | Q8: =M8 | T8: =AJ8 | U8: =Q8 | AJ8: =SUM(Y8:AI8) | AL8: =W8-AJ8
B9: TOTAL | C9: =SUM(C4:C8) | E9: =SUM(E4:E7) | G9: =SUM(G4:G7) | I9: =SUM(I4:I7) | J9: =SUM(J4:J7) | L9: =SUM(L4:L7) | M9: =SUM(M4:M7) | Q9: =SUM(Q4:Q7) | T9: =SUM(T4:T7) | U9: =Q9 | AJ9: =SUM(AJ4:AJ8) | AL9: =SUM(AL4:AL8)

Sheet G-Stat
C2: DAYS
C3: 1 | D3: 2 | E3: 3 | F3: 4 | G3: =F3+1 | H3: =G3+1 | I3: =H3+1 | J3: =I3+1 | K3: =J3+1 | L3: =K3+1 | M3: =L3+1 | N3: =M3+1 | ... AG3: =AF3+1
B4: GAS TOTAL | C4: =C26+C38+C50+C61 | D4: =D26+D38+D50+D61 | E4: =E26+E38+E50+E61 | F4: =F26+F38+F50+F61 | G4: =G26+G38+G50+G61 | H4: =H26+H38+H50+H61 | I4: =I26+I38+I50+I61 | J4: =J26+J38+J50+J61 | ... Z4: =Z26+Z38+Z50+Z61 | AA4: 0 | AB4: =AB26+AB38+AB50+AB61 | AC4: =AC26+AC38+AC50+AC61 | AD4: =AD26+AD38+AD50+AD61 | AE4: =AE26+AE38+AE50+AE61 | AF4: =AF26+AF38+AF50+AF61 | AG4: =AG26+AG38+AG50+AG61 | AH4: =Y4+Z4+AA4+AB4+AC4+AD4+AE4
B6: GAS GALLON | C6: ='1'!F8 | D6: =#REF! | E6: =#REF! | F6: =#REF! | G6: =#REF! | H6: =#REF! | I6: =#REF! | J6: =#REF! | K6: =#REF! | ... Z6: =#REF! | AA6: 0 | AB6: =#REF! | AC6: =#REF! | AD6: =#REF! | AE6: =#REF! | AF6: =#REF! | AG6: =#REF! | AH6: =Y6+Z6+AA6+AB6+AC6+AD6+AE6
B8: TOTAL CR/DR | C8: ='1'!F32 | D8: =#REF! | E8: =#REF! | F8: =#REF! | G8: =#REF! | H8: =#REF! | I8: =#REF! | J8: =#REF! | K8: =#REF! | ... AG8: =#REF! | AH8: =Y8+Z8+AA8+AB8+AC8+AD8+AE8
B10: POS SALE | C10: ='1'!F34 | D10: =#REF! | E10: =#REF! | F10: =#REF! | G10: =#REF! | H10: =#REF! | I10: =#REF! | J10: =#REF! | K10: =#REF! | ... AG10: =#REF! | AH10: =Y10+Z10+AA10+AB10+AC10+X10+W10
B12: DIFFERENCE | C12: =C10-C8 | D12: =D10-D8 | E12: =E10-E8 | F12: =F10-F8 | G12: =G10-G8 | H12: =H10-H8 | I12: =I10-I8 | J12: =J10-J8 | ... AG12: =AG10-AG8 | AH12: =Y12+Z12+AA12+AB12+AC12+AD12+AE12
B14: TANK 1 | C14: ='1'!H21 | D14: =C14+C15 | E14: =D14+D15 | F14: =E14+E15 | G14: =F14+F15 | H14: =G14+G15 | I14: =H14+H15 | J14: =I14+I15 | K14: =J14+J15 | ... AG14: =AF14+AF15
B15: TOTAL TANK1-PURCHASE | C15: 2 | D15: 3
B16: TANK 2 | C16: ='1'!P21 | D16: =C16+C17 | E16: =D16+D17 | F16: =E16+E17 | G16: =F16+F17 | H16: =G16+G17 | I16: =H16+H17 | J16: =I16+I17 | K16: =J16+J17 | ... AG16: =AF16+AF17
B17: TOTAL TANK2-PURCHASE | C17: 0
B18: TANK 3 | C18: ='1'!Z21 | D18: =C18+C19 | E18: =D18+D19 | F18: =E18+E19 | G18: =F18+F19 | H18: =G18+G19 | I18: =H18+H19 | J18: =I18+I19 | K18: =J18+J19 | ... AG18: =AF18+AF19
B19: TOTAL TANK3-PURCHASE
B21: DIESEL
B22: BEGINNING | C22: ='1'!E25 | D22: =#REF! | E22: =#REF! | F22: =#REF! | G22: =#REF! | H22: =#REF! | I22: =#REF! | J22: =#REF! | K22: =#REF! | ... AG22: =#REF!
B23: ENDING | C23: ='1'!E26 | D23: =#REF! | E23: =#REF! | F23: =#REF! | G23: =#REF! | H23: =#REF! | I23: =#REF! | J23: =#REF! | K23: =#REF! | ... AG23: =#REF!
B24: TOTAL | C24: ='1'!E27 | D24: =#REF! | E24: =#REF! | F24: =#REF! | G24: =#REF! | H24: =#REF! | I24: =#REF! | J24: =#REF! | K24: =#REF! | ... AG24: =#REF!
B25: PRICE | C25: ='1'!E28 | D25: =#REF! | E25: =#REF! | F25: =#REF! | G25: =#REF! | H25: =#REF! | I25: =#REF! | J25: =#REF! | K25: =#REF! | ... AG25: =#REF!
B26: VALUE | C26: ='1'!E29 | D26: =#REF! | E26: =#REF! | F26: =#REF! | G26: =#REF! | H26: =#REF! | I26: =#REF! | J26: =#REF! | K26: =#REF! | ... AG26: =#REF!
B31: REGULAR
C33: 1 | D33: 2 | E33: 3 | F33: 4 | G33: =F33+1 | H33: =G33+1 | I33: =H33+1 | J33: =I33+1 | K33: =J33+1 | L33: =K33+1 | M33: =L33+1 | N33: =M33+1 | ... AG33: =AF33+1
B34: BEGINNING | C34: ='1'!F25 | D34: =#REF! | E34: =#REF! | F34: =#REF! | G34: =#REF! | H34: =#REF! | I34: =#REF! | J34: =#REF! | K34: =#REF! | ... AG34: =#REF!
B35: ENDING | C35: ='1'!F26 | D35: =#REF! | E35: =#REF! | F35: =#REF! | G35: =#REF! | H35: =#REF! | I35: =#REF! | J35: =#REF! | K35: =#REF! | ... AG35: =#REF!
B36: TOTAL | C36: ='1'!F27 | D36: =#REF! | E36: =#REF! | F36: =#REF! | G36: =#REF! | H36: =#REF! | I36: =#REF! | J36: =#REF! | K36: =#REF! | ... AG36: =#REF!
B37: PRICE | C37: ='1'!F28 | D37: =#REF! | E37: =#REF! | F37: =#REF! | G37: =#REF! | H37: =#REF! | I37: =#REF! | J37: =#REF! | K37: =#REF! | ... AG37: =#REF!
B38: VALUE | C38: ='1'!F29 | D38: =#REF! | E38: =#REF! | F38: =#REF! | G38: =#REF! | H38: =#REF! | I38: =#REF! | J38: =#REF! | K38: =#REF! | ... AG38: =#REF!
B43: SUPER
C45: 1 | D45: 2 | E45: 3 | F45: 4 | G45: =F45+1 | H45: =G45+1 | I45: =H45+1 | J45: =I45+1 | K45: =J45+1 | L45: =K45+1 | M45: =L45+1 | N45: =M45+1 | ... AG45: =AF45+1
B46: BEGINNING | C46: ='1'!G25 | D46: =#REF! | E46: =#REF! | F46: =#REF! | G46: =#REF! | H46: =#REF! | I46: =#REF! | J46: =#REF! | K46: =#REF! | ... AG46: =#REF!
B47: ENDING | C47: ='1'!G26 | D47: =#REF! | E47: =#REF! | F47: =#REF! | G47: =#REF! | H47: =#REF! | I47: =#REF! | J47: =#REF! | K47: =#REF! | ... AG47: =#REF!
B48: TOTAL | C48: ='1'!G27 | D48: =#REF! | E48: =#REF! | F48: =#REF! | G48: =#REF! | H48: =#REF! | I48: =#REF! | J48: =#REF! | K48: =#REF! | ... AG48: =#REF!
B49: PRICE | C49: ='1'!G28 | D49: =#REF! | E49: =#REF! | F49: =#REF! | G49: =#REF! | H49: =#REF! | I49: =#REF! | J49: =#REF! | K49: =#REF! | ... AG49: =#REF!
B50: VALUE | C50: ='1'!G29 | D50: =#REF! | E50: =#REF! | F50: =#REF! | G50: =#REF! | H50: =#REF! | I50: =#REF! | J50: =#REF! | K50: =#REF! | ... AG50: =#REF!
B54: SPECIAL
C56: 1 | D56: 2 | E56: 3 | F56: 4 | G56: =F56+1 | H56: =G56+1 | I56: =H56+1 | J56: =I56+1 | K56: =J56+1 | L56: =K56+1 | M56: =L56+1 | N56: =M56+1 | ... AG56: =AF56+1
B57: BEGINNING | C57: ='1'!H25 | D57: =#REF! | E57: =#REF! | F57: =#REF! | G57: =#REF! | H57: =#REF! | I57: =#REF! | J57: =#REF! | K57: =#REF! | ... AG57: =#REF!
B58: ENDING | C58: ='1'!H26 | D58: =#REF! | E58: =#REF! | F58: =#REF! | G58: =#REF! | H58: =#REF! | I58: =#REF! | J58: =#REF! | K58: =#REF! | ... AG58: =#REF!
B59: TOTAL | C59: ='1'!H27 | D59: =#REF! | E59: =#REF! | F59: =#REF! | G59: =#REF! | H59: =#REF! | I59: =#REF! | J59: =#REF! | K59: =#REF! | ... AG59: =#REF!
B60: PRICE | C60: ='1'!H28 | D60: =#REF! | E60: =#REF! | F60: =#REF! | G60: =#REF! | H60: =#REF! | I60: =#REF! | J60: =#REF! | K60: =#REF! | ... AG60: =#REF!
B61: VALUE | C61: ='1'!H29 | D61: =#REF! | E61: =#REF! | F61: =#REF! | G61: =#REF! | H61: =#REF! | I61: =#REF! | J61: =#REF! | K61: =#REF! | ... AG61: =#REF!

Sheet G-Graph
B2: DIESEL
B18: REGULAR
B34: SUPER
B50: SPECIAL

Sheet S-Detail
B2: SALES | J2: COMMISSION | O2: PURCHASES
A3: Column1 | B3: SALES | C3: Column5 | D3: Column6 | E3: Column62 | F3: Column7 | G3: Column8 | H3: Column82 | I3: Column9 | J3: COMMISSIONS | K3: Column23 | L3: Column232 | M3: Column24 | N3: Column10 | O3: Column11 | P3: Column12 | Q3: Column13 | R3: Column132 | S3: Column133 | T3: Column134 | U3: Column1342 | V3: Column135 | W3: Column136 | X3: Column137 | Y3: Column14 | Z3: Column15
A5: DAY | B5: GALLON SOLD | C5: GAS | D5: LOTTO | E5: PHONECD | F5: INSIDE SALES | G5: NET SALES | H5: NET SALE COMP | I5: SALES TAX | J5: LOTTO | K5: PHONECD | L5: ATM | M5: GROCERY (30%) | N5: GAS | O5: GAS | P5: LOTTO | Q5: PHONECDS | R5: BEER | S5: CIG + TOB | T5: SODA | U5: CHIPS | V5: CANDIES | W5: OAKFARMS | X5: ICE CREAM | Y5: GROCERY | Z5: OTHERS
A6: 1 | B6: ='1'!F8 | C6: ='1'!F15 | D6: ='1'!F7 | E6: ='1'!F6 | F6: ='1'!F18 | G6: ='1'!L7 | H6: =Table1[[#This Row],[Column7]]-Table1[[#This Row],[Column62]] | I6: ='1'!F17 | M6: =Table1[[#This Row],[Column7]]-Table1[[#This Row],[Column62]]*30%
A7: 2 | B7: =#REF! | C7: =#REF! | D7: =#REF! | E7: =#REF! | F7: =#REF! | G7: =#REF! | H7: =Table1[[#This Row],[Column7]]-Table1[[#This Row],[Column62]] | I7: =#REF! | M7: =Table1[[#This Row],[Column7]]-Table1[[#This Row],[Column62]]*30% | S7: 22
A8: 3 | B8: =#REF! | C8: =#REF! | D8: =#REF! | E8: =#REF! | F8: =#REF! | G8: =#REF! | H8: =Table1[[#This Row],[Column7]]-Table1[[#This Row],[Column62]] | I8: =#REF! | M8: =Table1[[#This Row],[Column7]]-Table1[[#This Row],[Column62]]*30%
A9: 4 | B9: =#REF! | C9: =#REF! | D9: =#REF! | E9: =#REF! | F9: =#REF! | G9: =#REF! | H9: =Table1[[#This Row],[Column7]]-Table1[[#This Row],[Column62]] | I9: =#REF! | M9: =Table1[[#This Row],[Column7]]-Table1[[#This Row],[Column62]]*30% | R9: 2
A10: 5 | B10: =#REF! | C10: =#REF! | D10: =#REF! | E10: =#REF! | F10: =#REF! | G10: =#REF! | H10: =Table1[[#This Row],[Column7]]-Table1[[#This Row],[Column62]] | I10: =#REF! | M10: =Table1[[#This Row],[Column7]]-Table1[[#This Row],[Column62]]*30%
A11: 6 | B11: =#REF! | C11: =#REF! | D11: =#REF! | E11: =#REF! | F11: =#REF! | G11: =#REF! | H11: =Table1[[#This Row],[Column7]]-Table1[[#This Row],[Column62]] | I11: =#REF! | M11: =Table1[[#This Row],[Column7]]-Table1[[#This Row],[Column62]]*30%
A12: 7 | B12: =#REF! | C12: =#REF! | D12: =#REF! | E12: =#REF! | F12: =#REF! | G12: =#REF! | H12: =Table1[[#This Row],[Column7]]-Table1[[#This Row],[Column62]] | I12: =#REF! | M12: =Table1[[#This Row],[Column7]]-Table1[[#This Row],[Column62]]*30% | R12: 20
A13: W1 | B13: =SUBTOTAL(109,B6:B12) | C13: =SUBTOTAL(109,C4:C12) | D13: =SUBTOTAL(109,D4:D12) | E13: =SUBTOTAL(109,E4:E12) | F13: =SUBTOTAL(109,F4:F12) | G13: =SUBTOTAL(109,G4:G12) | H13: =SUBTOTAL(109,H4:H12) | I13: =SUBTOTAL(109,I4:I12) | J13: =SUBTOTAL(109,J4:J12) | ... Z13: =SUBTOTAL(109,Z4:Z12)
A15: 8 | B15: =#REF! | C15: =#REF! | D15: =#REF! | E15: =#REF! | F15: =#REF! | G15: =#REF! | H15: =Table1[[#This Row],[Column7]]-Table1[[#This Row],[Column62]] | I15: =#REF! | M15: =Table1[[#This Row],[Column7]]-Table1[[#This Row],[Column62]]*30%
A16: 9 | B16: =#REF! | C16: =#REF! | D16: =#REF! | E16: =#REF! | F16: =#REF! | G16: =#REF! | H16: =Table1[[#This Row],[Column7]]-Table1[[#This Row],[Column62]] | I16: =#REF! | M16: =Table1[[#This Row],[Column7]]-Table1[[#This Row],[Column62]]*30% | R16: 0
A17: 10 | B17: =#REF! | C17: =#REF! | D17: =#REF! | E17: =#REF! | F17: =#REF! | G17: =#REF! | H17: =Table1[[#This Row],[Column7]]-Table1[[#This Row],[Column62]] | I17: =#REF! | M17: =Table1[[#This Row],[Column7]]-Table1[[#This Row],[Column62]]*30% | R17: 66
A18: 11 | B18: =#REF! | C18: =#REF! | D18: =#REF! | E18: =#REF! | F18: =#REF! | G18: =#REF! | H18: =Table1[[#This Row],[Column7]]-Table1[[#This Row],[Column62]] | I18: =#REF! | M18: =Table1[[#This Row],[Column7]]-Table1[[#This Row],[Column62]]*30% | R18: 20
A19: 12 | B19: =#REF! | C19: =#REF! | D19: =#REF! | E19: =#REF! | F19: =#REF! | G19: =#REF! | H19: =Table1[[#This Row],[Column7]]-Table1[[#This Row],[Column62]] | I19: =#REF! | M19: =Table1[[#This Row],[Column7]]-Table1[[#This Row],[Column62]]*30%
A20: 13 | B20: =#REF! | C20: =#REF! | D20: =#REF! | E20: =#REF! | F20: =#REF! | G20: =#REF! | H20: =Table1[[#This Row],[Column7]]-Table1[[#This Row],[Column62]] | I20: =#REF! | M20: =Table1[[#This Row],[Column7]]-Table1[[#This Row],[Column62]]*30%
A21: 14 | B21: =#REF! | C21: =#REF! | D21: =#REF! | E21: =#REF! | F21: =#REF! | G21: =#REF! | H21: =Table1[[#This Row],[Column7]]-Table1[[#This Row],[Column62]] | I21: =#REF! | M21: =Table1[[#This Row],[Column7]]-Table1[[#This Row],[Column62]]*30% | R21: 1 | S21: 6
A22: W2 | B22: =SUBTOTAL(109,B15:B21) | C22: =SUBTOTAL(109,C15:C21) | D22: =SUBTOTAL(109,D15:D21) | E22: =SUBTOTAL(109,E15:E21) | F22: =SUBTOTAL(109,F15:F21) | G22: =SUBTOTAL(109,G15:G21) | H22: =SUBTOTAL(109,H15:H21) | I22: =SUBTOTAL(109,I15:I21) | ... Z22: =SUBTOTAL(109,Z15:Z21)
A24: 15 | B24: =#REF! | C24: =#REF! | D24: =#REF! | E24: =#REF! | F24: =#REF! | G24: =#REF! | H24: =Table1[[#This Row],[Column7]]-Table1[[#This Row],[Column62]] | I24: =#REF! | M24: =Table1[[#This Row],[Column7]]-Table1[[#This Row],[Column62]]*30%
A25: 16 | B25: =#REF! | C25: =#REF! | D25: =#REF! | E25: =#REF! | F25: =#REF! | G25: =#REF! | H25: =Table1[[#This Row],[Column7]]-Table1[[#This Row],[Column62]] | I25: =#REF! | M25: =Table1[[#This Row],[Column7]]-Table1[[#This Row],[Column62]]*30%
A26: 17 | B26: =#REF! | C26: =#REF! | D26: =#REF! | E26: =#REF! | F26: =#REF! | G26: =#REF! | H26: =Table1[[#This Row],[Column7]]-Table1[[#This Row],[Column62]] | I26: =#REF! | M26: =Table1[[#This Row],[Column7]]-Table1[[#This Row],[Column62]]*30% | R26: 20
A27: 18 | B27: =#REF! | C27: =#REF! | D27: =#REF! | E27: =#REF! | F27: =#REF! | G27: =#REF! | H27: =Table1[[#This Row],[Column7]]-Table1[[#This Row],[Column62]] | I27: =#REF! | M27: =Table1[[#This Row],[Column7]]-Table1[[#This Row],[Column62]]*30%
A28: 19 | B28: =#REF! | C28: =#REF! | D28: =#REF! | E28: =#REF! | F28: =#REF! | G28: =#REF! | H28: =Table1[[#This Row],[Column7]]-Table1[[#This Row],[Column62]] | I28: =#REF! | M28: =Table1[[#This Row],[Column7]]-Table1[[#This Row],[Column62]]*30% | R28: 44
A29: 20 | B29: =#REF! | C29: =#REF! | D29: =#REF! | E29: =#REF! | F29: =#REF! | G29: =#REF! | H29: =Table1[[#This Row],[Column7]]-Table1[[#This Row],[Column62]] | I29: =#REF! | M29: =Table1[[#This Row],[Column7]]-Table1[[#This Row],[Column62]]*30%
A30: 21 | B30: =#REF! | C30: =#REF! | D30: =#REF! | E30: =#REF! | F30: =#REF! | G30: =#REF! | H30: =Table1[[#This Row],[Column7]]-Table1[[#This Row],[Column62]] | I30: =#REF! | M30: =Table1[[#This Row],[Column7]]-Table1[[#This Row],[Column62]]*30%
A31: W3 | B31: =SUM(B24:B30) | C31: =SUBTOTAL(109,C15:C21) | D31: =SUBTOTAL(109,D15:D21) | E31: =SUBTOTAL(109,E15:E21) | F31: =SUBTOTAL(109,F15:F21) | G31: =SUBTOTAL(109,G15:G21) | H31: =SUBTOTAL(109,H15:H21) | I31: =SUBTOTAL(109,I15:I21) | J31: =SUBTOTAL(109,J15:J21) | ... Z31: =SUBTOTAL(109,Z15:Z21)
A33: 22 | B33: =#REF! | C33: =#REF! | D33: =#REF! | E33: =#REF! | F33: =#REF! | G33: =#REF! | H33: =Table1[[#This Row],[Column7]]-Table1[[#This Row],[Column62]] | I33: =#REF! | M33: =Table1[[#This Row],[Column7]]-Table1[[#This Row],[Column62]]*30%
A34: 23 | B34: =#REF! | C34: =#REF! | D34: =#REF! | E34: =#REF! | F34: =#REF! | G34: =#REF! | H34: =Table1[[#This Row],[Column7]]-Table1[[#This Row],[Column62]] | I34: =#REF! | M34: =Table1[[#This Row],[Column7]]-Table1[[#This Row],[Column62]]*30%
A35: 24 | B35: =#REF! | C35: =#REF! | D35: =#REF! | E35: =#REF! | F35: =#REF! | G35: =#REF! | H35: =Table1[[#This Row],[Column7]]-Table1[[#This Row],[Column62]] | I35: =#REF! | M35: =Table1[[#This Row],[Column7]]-Table1[[#This Row],[Column62]]*30% | R35: 1
A36: 25 | B36: =#REF! | C36: =#REF! | D36: =#REF! | E36: =#REF! | F36: =#REF! | G36: =#REF! | H36: =Table1[[#This Row],[Column7]]-Table1[[#This Row],[Column62]] | I36: =#REF! | M36: =Table1[[#This Row],[Column7]]-Table1[[#This Row],[Column62]]*30% | R36: 2
A37: 26 | B37: =#REF! | C37: =#REF! | D37: =#REF! | E37: =#REF! | F37: =#REF! | G37: =#REF! | H37: =Table1[[#This Row],[Column7]]-Table1[[#This Row],[Column62]] | I37: =#REF! | M37: =Table1[[#This Row],[Column7]]-Table1[[#This Row],[Column62]]*30%
A38: 27 | B38: =#REF! | C38: =#REF! | D38: =#REF! | E38: =#REF! | F38: =#REF! | G38: =#REF! | H38: =Table1[[#This Row],[Column7]]-Table1[[#This Row],[Column62]] | I38: =#REF! | M38: =Table1[[#This Row],[Column7]]-Table1[[#This Row],[Column62]]*30%
A39: 28 | B39: =#REF! | C39: =#REF! | D39: =#REF! | E39: =#REF! | F39: =#REF! | G39: =#REF! | H39: =Table1[[#This Row],[Column7]]-Table1[[#This Row],[Column62]] | I39: =#REF! | M39: =Table1[[#This Row],[Column7]]-Table1[[#This Row],[Column62]]*30% | R39: 3
A40: W4 | B40: =SUBTOTAL(109,B33:B39) | C40: =SUBTOTAL(109,C33:C39) | D40: =SUBTOTAL(109,D33:D39) | E40: =SUBTOTAL(109,E33:E39) | F40: =SUBTOTAL(109,F33:F39) | G40: =SUBTOTAL(109,G33:G39) | H40: =SUBTOTAL(109,H33:H39) | I40: =SUBTOTAL(109,I33:I39) | ... Z40: =SUBTOTAL(109,Z33:Z39)
A42: 29 | B42: =#REF! | C42: =#REF! | D42: =#REF! | E42: =#REF! | F42: =#REF! | G42: =#REF! | H42: =Table1[[#This Row],[Column7]]-Table1[[#This Row],[Column62]] | I42: =#REF! | M42: =Table1[[#This Row],[Column7]]-Table1[[#This Row],[Column62]]*30%
A43: 30 | B43: =#REF! | C43: =#REF! | D43: =#REF! | E43: =#REF! | F43: =#REF! | G43: =#REF! | H43: =Table1[[#This Row],[Column7]]-Table1[[#This Row],[Column62]] | I43: =#REF! | M43: =Table1[[#This Row],[Column7]]-Table1[[#This Row],[Column62]]*30%
A44: 31 | B44: =#REF! | C44: =#REF! | D44: =#REF! | E44: =#REF! | F44: =#REF! | G44: =#REF! | H44: =Table1[[#This Row],[Column7]]-Table1[[#This Row],[Column62]] | I44: =#REF! | M44: =Table1[[#This Row],[Column7]]-Table1[[#This Row],[Column62]]*30%
A45: W5 | B45: =SUBTOTAL(109,B42:B44) | C45: =SUBTOTAL(109,C42:C44) | D45: =SUBTOTAL(109,D42:D44) | E45: =SUBTOTAL(109,E42:E44) | F45: =SUBTOTAL(109,F42:F44) | G45: =SUBTOTAL(109,G42:G44) | H45: =SUBTOTAL(109,H42:H44) | I45: =SUBTOTAL(109,I42:I44) | ... Z45: =SUBTOTAL(109,Z42:Z44)
B48: =B34+B35+B36+B38+B39+B42 | C48: =C34+C35+C36+C38+C39+C42 | D48: =D13+D22+D31+D40+D45 | E48: =E34+E35+E36+E38+E39+E42 | F48: =F34+F35+F38+F39+F42 | G48: =G13+G22+G31+G40+G45 | H48: =H13+H22+H31+H40+H45 | I48: =I13+I22+I31+I40+I45
...

Sheet S-Graph

Sheet Emp-Stat
B2: Day | C2: Employee: | F2: Employee: | I2: Employee:
C3: M | D3: No of Sales | E3: Ave Sales | F3: E | G3: No of Sales | H3: Ave Sales | I3: N | J3: No of Sales | K3: Ave Sales
B4: 1 | C4: ='1'!D9 | D4: ='1'!E10 | E4: ='1'!G10 | F4: ='1'!D11 | G4: ='1'!E12 | H4: ='1'!G12 | I4: ='1'!D13 | J4: ='1'!E14 | K4: ='1'!G14
B5: 2 | C5: =#REF! | D5: =#REF! | E5: =#REF! | F5: =#REF! | G5: =#REF! | H5: =#REF! | I5: =#REF! | J5: =#REF! | K5: =#REF!
B6: 3 | C6: =#REF! | D6: =#REF! | E6: =#REF! | F6: =#REF! | G6: =#REF! | H6: =#REF! | I6: =#REF! | J6: =#REF! | K6: =#REF!
B7: 4 | C7: =#REF! | D7: =#REF! | E7: =#REF! | F7: =#REF! | G7: =#REF! | H7: =#REF! | I7: =#REF! | J7: =#REF! | K7: =#REF!
B8: 5 | C8: =#REF! | D8: =#REF! | E8: =#REF! | F8: =#REF! | G8: =#REF! | H8: =#REF! | I8: =#REF! | J8: =#REF! | K8: =#REF!
B9: 6 | C9: =#REF! | D9: =#REF! | E9: =#REF! | F9: =#REF! | G9: =#REF! | H9: =#REF! | I9: =#REF! | J9: =#REF! | K9: =#REF!
B10: 7 | C10: =#REF! | D10: =#REF! | E10: =#REF! | F10: =#REF! | G10: =#REF! | H10: =#REF! | I10: =#REF! | J10: =#REF! | K10: =#REF!
A11: Total | B11: W1 | C11: =SUM(C4:C10) | D11: =SUM(D4:D10) | E11: =SUM(E4:E10) | F11: =SUM(F4:F10) | G11: =SUM(G4:G10) | H11: =SUM(H4:H10) | I11: =SUM(I4:I10) | J11: =SUM(J4:J10) | K11: =SUM(K4:K10)
B12: =B10+1 | C12: =#REF! | D12: =#REF! | E12: =#REF! | F12: =#REF! | G12: =#REF! | H12: =#REF! | I12: =#REF! | J12: =#REF! | K12: =#REF!
B13: =B12+1 | C13: =#REF! | D13: =#REF! | E13: =#REF! | F13: =#REF! | G13: =#REF! | H13: =#REF! | I13: =#REF! | J13: =#REF! | K13: =#REF!
B14: =B13+1 | C14: =#REF! | D14: =#REF! | E14: =#REF! | F14: =#REF! | G14: =#REF! | H14: =#REF! | I14: =#REF! | J14: =#REF! | K14: =#REF!
B15: =B14+1 | C15: =#REF! | D15: =#REF! | E15: =#REF! | F15: =#REF! | G15: =#REF! | H15: =#REF! | I15: =#REF! | J15: =#REF! | K15: =#REF!
B16: =B15+1 | C16: =#REF! | D16: =#REF! | E16: =#REF! | F16: =#REF! | G16: =#REF! | H16: =#REF! | I16: =#REF! | J16: =#REF! | K16: =#REF!
B17: =B16+1 | C17: =#REF! | D17: =#REF! | E17: =#REF! | F17: =#REF! | G17: =#REF! | H17: =#REF! | I17: =#REF! | J17: =#REF! | K17: =#REF!
B18: =B17+1 | C18: =#REF! | D18: =#REF! | E18: =#REF! | F18: =#REF! | G18: =#REF! | H18: =#REF! | I18: =#REF! | J18: =#REF! | K18: =#REF!
A19: Total | B19: W2 | C19: =SUM(C12:C18) | D19: =SUM(D12:D18) | E19: =SUM(E12:E18) | F19: =SUM(F12:F18) | G19: =SUM(G12:G18) | H19: =SUM(H12:H18) | I19: =SUM(I12:I18) | J19: =SUM(J12:J18) | K19: =SUM(K12:K18)
B20: =B18+1 | C20: =#REF! | D20: =#REF! | E20: =#REF! | F20: =#REF! | G20: =#REF! | H20: =#REF! | I20: =#REF! | J20: =#REF! | K20: =#REF!
B21: =B20+1 | C21: =#REF! | D21: =#REF! | E21: =#REF! | F21: =#REF! | G21: =#REF! | H21: =#REF! | I21: =#REF! | J21: =#REF! | K21: =#REF!
B22: =B21+1 | C22: =#REF! | D22: =#REF! | E22: =#REF! | F22: =#REF! | G22: =#REF! | H22: =#REF! | I22: =#REF! | J22: =#REF! | K22: =#REF!
B23: =B22+1 | C23: =#REF! | D23: =#REF! | E23: =#REF! | F23: =#REF! | G23: =#REF! | H23: =#REF! | I23: =#REF! | J23: =#REF! | K23: =#REF!
B24: =B23+1 | C24: =#REF! | D24: =#REF! | E24: =#REF! | F24: =#REF! | G24: =#REF! | H24: =#REF! | I24: =#REF! | J24: =#REF! | K24: =#REF!
B25: =B24+1 | C25: =#REF! | D25: =#REF! | E25: =#REF! | F25: =#REF! | G25: =#REF! | H25: =#REF! | I25: =#REF! | J25: =#REF! | K25: =#REF!
B26: =B25+1 | C26: =#REF! | D26: =#REF! | E26: =#REF! | F26: =#REF! | G26: =#REF! | H26: =#REF! | I26: =#REF! | J26: =#REF! | K26: =#REF!
A27: Total | B27: W3 | C27: =SUM(C20:C26) | D27: =SUM(D20:D26) | E27: =SUM(E20:E26) | F27: =SUM(F20:F26) | G27: =SUM(G20:G26) | H27: =SUM(H20:H26) | I27: =SUM(I20:I26) | J27: =SUM(J20:J26) | K27: =SUM(K20:K26)
B28: =B26+1 | C28: =#REF! | D28: =#REF! | E28: =#REF! | F28: =#REF! | G28: =#REF! | H28: =#REF! | I28: =#REF! | J28: =#REF! | K28: =#REF!
B29: =B28+1 | C29: =#REF! | D29: =#REF! | E29: =#REF! | F29: =#REF! | G29: =#REF! | H29: =#REF! | I29: =#REF! | J29: =#REF! | K29: =#REF!
B30: =B29+1 | C30: =#REF! | D30: =#REF! | E30: =#REF! | F30: =#REF! | G30: =#REF! | H30: =#REF! | I30: =#REF! | J30: =#REF! | K30: =#REF!
B31: =B30+1 | C31: =#REF! | D31: =#REF! | E31: =#REF! | F31: =#REF! | G31: =#REF! | H31: =#REF! | I31: =#REF! | J31: =#REF! | K31: =#REF!
B32: =B31+1 | C32: =#REF! | D32: =#REF! | E32: =#REF! | F32: =#REF! | G32: =#REF! | H32: =#REF! | I32: =#REF! | J32: =#REF! | K32: =#REF!
B33: =B32+1 | C33: =#REF! | D33: =#REF! | E33: =#REF! | F33: =#REF! | G33: =#REF! | H33: =#REF! | I33: =#REF! | J33: =#REF! | K33: =#REF!
B34: =B33+1 | C34: =#REF! | D34: =#REF! | E34: =#REF! | F34: =#REF! | G34: =#REF! | H34: =#REF! | I34: =#REF! | J34: =#REF! | K34: =#REF!
A35: Total | B35: W4 | C35: =SUM(C28:C34) | D35: =SUM(D28:D34) | E35: =SUM(E28:E34) | F35: =SUM(F28:F34) | G35: =SUM(G28:G34) | H35: =SUM(H28:H34) | I35: =SUM(I28:I34) | J35: =SUM(J28:J34) | K35: =SUM(K28:K34)
B36: =B34+1 | C36: =#REF! | D36: =#REF! | E36: =#REF! | F36: =#REF! | G36: =#REF! | H36: =#REF! | I36: =#REF! | J36: =#REF! | K36: =#REF!
B37: =B36+1 | C37: =#REF! | D37: =#REF! | E37: =#REF! | F37: =#REF! | G37: =#REF! | H37: =#REF! | I37: =#REF! | J37: =#REF! | K37: =#REF!
B38: =B37+1 | C38: =#REF! | D38: =#REF! | E38: =#REF! | F38: =#REF! | G38: =#REF! | H38: =#REF! | I38: =#REF! | J38: =#REF! | K38: =#REF!
C39: =SUM(C36:C38) | D39: =SUM(D36:D38) | E39: =SUM(E36:E38) | F39: =SUM(F36:F38) | G39: =SUM(G36:G38) | H39: =SUM(H36:H38) | I39: =SUM(I36:I38) | J39: =SUM(J36:J38) | K39: =SUM(K36:K38)
B40: Total | C40: =C11+C19+C27+C39 | D40: =D11+D19+D27+D39 | E40: =E11+E19+E27+E39 | F40: =F11+F19+F27+F39 | G40: =G11+G19+G27+G39 | H40: =H11+H19+H27+H39 | I40: =I11+I19+I27+I39 | J40: =J11+J19+J27+J39 | K40: =K11+K19+K27+K39

Sheet INV-1
C2: WEEK | D2: TOTAL BEGINNING INVENTORY | E2: TOTAL PURCHASES | F2: TOTAL SOLD ITEMS | G2: % SALE | H2: TOTAL ENDING INVENTORY
C3: Column1 | D3: Column2 | E3: Column3 | F3: Column4 | G3: Column42 | H3: Column5
C4: 1 | D4: ='INV-2'!B5+'INV-2'!G5+'INV-2'!L5+'INV-2'!B13+'INV-2'!G13+'INV-2'!L13+'INV-2'!B21+'INV-2'!G21+'INV-2'!L21+'INV-2'!B29+'INV-2'!G29+'INV-2'!L29+'INV-2'!B37+'INV-2'!G37+'INV-2'!L37 | E4: ='INV-2'!C21+'INV-2'!H21+'INV-2'!M21+'INV-2'!C29+'INV-2'!H29+'INV-2'!M29+'INV-2'!C37+'INV-2'!H37+'INV-2'!M37 | F4: ='INV-2'!D5+'INV-2'!I5+'INV-2'!N5+'INV-2'!D13+'INV-2'!I13+'INV-2'!N13+'INV-2'!D21+'INV-2'!I21+'INV-2'!N21+'INV-2'!D37+'INV-2'!I37+'INV-2'!N37 | G4: =Table4[[#This Row],[Column2]]+Table4[[#This Row],[Column3]]/Table4[[#This Row],[Column4]]*100 | H4: ='INV-2'!E5+'INV-2'!J5+'INV-2'!O5+'INV-2'!E13+'INV-2'!J13+'INV-2'!O13+'INV-2'!E21+'INV-2'!J21+'INV-2'!O21+'INV-2'!E29+'INV-2'!J29+'INV-2'!O29+'INV-2'!E37+'INV-2'!J37+'INV-2'!O37
C5: 2 | D5: ='INV-2'!B6+'INV-2'!G6+'INV-2'!L6+'INV-2'!B14+'INV-2'!G14+'INV-2'!L14+'INV-2'!B22+'INV-2'!G22+'INV-2'!L22+'INV-2'!B30+'INV-2'!G30+'INV-2'!L30+'INV-2'!B38+'INV-2'!G38+'INV-2'!L38 | E5: ='INV-2'!C22+'INV-2'!H22+'INV-2'!M22+'INV-2'!C30+'INV-2'!H30+'INV-2'!M30+'INV-2'!C38+'INV-2'!H38+'INV-2'!M38 | F5: ='INV-2'!D6+'INV-2'!I6+'INV-2'!N6+'INV-2'!D14+'INV-2'!I14+'INV-2'!N14+'INV-2'!D22+'INV-2'!I22+'INV-2'!N22+'INV-2'!D38+'INV-2'!I38+'INV-2'!N38 | G5: =Table4[[#This Row],[Column2]]+Table4[[#This Row],[Column3]]/Table4[[#This Row],[Column4]]*100 | H5: ='INV-2'!E6+'INV-2'!J6+'INV-2'!O6+'INV-2'!E14+'INV-2'!J14+'INV-2'!O14+'INV-2'!E22+'INV-2'!J22+'INV-2'!O22+'INV-2'!E30+'INV-2'!J30+'INV-2'!O30+'INV-2'!E38+'INV-2'!J38+'INV-2'!O38
C6: 3 | D6: ='INV-2'!B7+'INV-2'!G7+'INV-2'!L7+'INV-2'!B15+'INV-2'!G15+'INV-2'!L15+'INV-2'!B23+'INV-2'!G23+'INV-2'!L23+'INV-2'!B31+'INV-2'!G31+'INV-2'!L31+'INV-2'!B39+'INV-2'!G39+'INV-2'!L39 | E6: ='INV-2'!C23+'INV-2'!H23+'INV-2'!M23+'INV-2'!C31+'INV-2'!H31+'INV-2'!M31+'INV-2'!C39+'INV-2'!H39+'INV-2'!M39 | F6: ='INV-2'!D7+'INV-2'!I7+'INV-2'!N7+'INV-2'!D15+'INV-2'!I15+'INV-2'!N15+'INV-2'!D23+'INV-2'!I23+'INV-2'!N23+'INV-2'!D39+'INV-2'!I39+'INV-2'!N39 | G6: =Table4[[#This Row],[Column2]]+Table4[[#This Row],[Column3]]/Table4[[#This Row],[Column4]]*100 | H6: ='INV-2'!E7+'INV-2'!J7+'INV-2'!O7+'INV-2'!E15+'INV-2'!J15+'INV-2'!O15+'INV-2'!E23+'INV-2'!J23+'INV-2'!O23+'INV-2'!E31+'INV-2'!J31+'INV-2'!O31+'INV-2'!E39+'INV-2'!J39+'INV-2'!O39
C7: 4 | D7: ='INV-2'!B8+'INV-2'!G8+'INV-2'!L8+'INV-2'!B16+'INV-2'!G16+'INV-2'!L16+'INV-2'!B24+'INV-2'!G24+'INV-2'!L24+'INV-2'!B32+'INV-2'!G32+'INV-2'!L32+'INV-2'!B40+'INV-2'!G40+'INV-2'!L40 | E7: ='INV-2'!C24+'INV-2'!H24+'INV-2'!M24+'INV-2'!C32+'INV-2'!H32+'INV-2'!M32+'INV-2'!C40+'INV-2'!H40+'INV-2'!M40 | F7: ='INV-2'!D8+'INV-2'!I8+'INV-2'!N8+'INV-2'!D16+'INV-2'!I16+'INV-2'!N16+'INV-2'!D24+'INV-2'!I24+'INV-2'!N24+'INV-2'!D40+'INV-2'!I40+'INV-2'!N40 | G7: =Table4[[#This Row],[Column2]]+Table4[[#This Row],[Column3]]/Table4[[#This Row],[Column4]]*100 | H7: ='INV-2'!E8+'INV-2'!J8+'INV-2'!O8+'INV-2'!E16+'INV-2'!J16+'INV-2'!O16+'INV-2'!E24+'INV-2'!J24+'INV-2'!O24+'INV-2'!E32+'INV-2'!J32+'INV-2'!O32+'INV-2'!E40+'INV-2'!J40+'INV-2'!O40
C8: 5 | D8: ='INV-2'!B9+'INV-2'!G9+'INV-2'!L9+'INV-2'!B17+'INV-2'!G17+'INV-2'!L17+'INV-2'!B25+'INV-2'!G25+'INV-2'!L25+'INV-2'!B33+'INV-2'!G33+'INV-2'!L33+'INV-2'!B41+'INV-2'!G41+'INV-2'!L41 | E8: ='INV-2'!C25+'INV-2'!H25+'INV-2'!M25+'INV-2'!C33+'INV-2'!H33+'INV-2'!M33+'INV-2'!C41+'INV-2'!H41+'INV-2'!M41 | F8: ='INV-2'!D9+'INV-2'!I9+'INV-2'!N9+'INV-2'!D17+'INV-2'!I17+'INV-2'!N17+'INV-2'!D25+'INV-2'!I25+'INV-2'!N25+'INV-2'!D41+'INV-2'!I41+'INV-2'!N41 | G8: =Table4[[#This Row],[Column2]]+Table4[[#This Row],[Column3]]/Table4[[#This Row],[Column4]]*100 | H8: ='INV-2'!E9+'INV-2'!J9+'INV-2'!O9+'INV-2'!E17+'INV-2'!J17+'INV-2'!O17+'INV-2'!E25+'INV-2'!J25+'INV-2'!O25+'INV-2'!E33+'INV-2'!J33+'INV-2'!O33+'INV-2'!E41+'INV-2'!J41+'INV-2'!O41
C11: # | D11: ITEMS | E11: TOTAL BEGINNING INVENTORY | F11: TOTAL PURCHASE | G11: TOTAL SOLD | H11: TOTAL ENDING
C12: 1 | D12: ='INV-2'!B3 | E12: ='INV-2'!B5+'INV-2'!B6+'INV-2'!B7+'INV-2'!B8+'INV-2'!B9 | F12: ='INV-2'!C5+'INV-2'!C6+'INV-2'!C7+'INV-2'!C8+'INV-2'!C9 | G12: ='INV-2'!D5+'INV-2'!D6+'INV-2'!D7+'INV-2'!D8+'INV-2'!D9 | H12: ='INV-2'!E10
C13: 2 | D13: ='INV-2'!G3 | E13: ='INV-2'!G5+'INV-2'!G6+'INV-2'!G7+'INV-2'!G8+'INV-2'!G9 | F13: ='INV-2'!H5+'INV-2'!H6+'INV-2'!H7+'INV-2'!H8+'INV-2'!H9 | G13: ='INV-2'!I10 | H13: ='INV-2'!J10
C14: 3 | D14: ='INV-2'!L3 | E14: ='INV-2'!L10 | F14: ='INV-2'!M10 | G14: ='INV-2'!N10 | H14: ='INV-2'!O10
C15: 4 | D15: ='INV-2'!B11 | E15: ='INV-2'!B18 | F15: ='INV-2'!C18 | G15: ='INV-2'!D18 | H15: ='INV-2'!E18
C16: 5 | D16: ='INV-2'!G11 | E16: ='INV-2'!G18 | F16: ='INV-2'!H18 | G16: ='INV-2'!I18 | H16: ='INV-2'!J18
C17: 6 | D17: ='INV-2'!L11 | E17: ='INV-2'!L18 | F17: ='INV-2'!M18 | G17: ='INV-2'!N18 | H17: ='INV-2'!O18
C18: 7
C19: 8
C20: 9
C21: 10

Sheet INV-2
A2: INVENTORY BY ITEMS
B3: CIG/TOBACCO | G3: BEER | L3: SODA
A4: DAY | B4: BEGINNING INVENTORY | C4: TOTAL PURCHASE | D4: INVENTORY SOLD OUT | E4: ENDING INVENTORY | G4: BEGINNING INVENTORY | H4: TOTAL PURCHASE | I4: INVENTORY SOLD OUT | J4: ENDING INVENTORY | L4: BEGINNING INVENTORY | M4: TOTAL PURCHASE | N4: INVENTORY SOLD OUT | O4: ENDING INVENTORY
A5: 1 | C5: ='S-Detail'!S6+'S-Detail'!S7+'S-Detail'!S8+'S-Detail'!S9+'S-Detail'!S10+'S-Detail'!S11+'S-Detail'!S12 | E5: =B5+C5-D5 | H5: ='S-Detail'!R6+'S-Detail'!R7+'S-Detail'!R8+'S-Detail'!R9+'S-Detail'!R10+'S-Detail'!R11+'S-Detail'!R12 | J5: =G5+H5-I5 | M5: ='S-Detail'!T6+'S-Detail'!T7+'S-Detail'!T8+'S-Detail'!T9+'S-Detail'!T10+'S-Detail'!T11+'S-Detail'!T12 | O5: =L5+M5-N5
A6: 2 | C6: ='S-Detail'!S15+'S-Detail'!S16+'S-Detail'!S17+'S-Detail'!S18+'S-Detail'!S19+'S-Detail'!S20+'S-Detail'!S21 | E6: =B6+C6-D6 | H6: ='S-Detail'!R15+'S-Detail'!R16+'S-Detail'!R17+'S-Detail'!R18+'S-Detail'!R19+'S-Detail'!R20+'S-Detail'!R21 | J6: =G6+H6-I6 | O6: =L6+M6-N6
A7: 3 | C7: ='S-Detail'!S24+'S-Detail'!S25+'S-Detail'!S26+'S-Detail'!S27+'S-Detail'!S28+'S-Detail'!S29+'S-Detail'!S30 | E7: =B7+C7-D7 | H7: ='S-Detail'!R24+'S-Detail'!R25+'S-Detail'!R26+'S-Detail'!R27+'S-Detail'!R28+'S-Detail'!R29+'S-Detail'!R30 | J7: =G7+H7-I7 | O7: =L7+M7-N7
A8: 4 | B8: 0 | C8: ='S-Detail'!S33+'S-Detail'!S34+'S-Detail'!S35+'S-Detail'!S36+'S-Detail'!S37+'S-Detail'!S38+'S-Detail'!S39 | E8: =B8+C8-D8 | H8: ='S-Detail'!R33+'S-Detail'!R34+'S-Detail'!R35+'S-Detail'!R36+'S-Detail'!R37+'S-Detail'!R38+'S-Detail'!R39 | I8: 2 | J8: =G8+H8-I8 | O8: =L8+M8-N8
A9: 5 | B9: 0 | C9: ='S-Detail'!S42+'S-Detail'!S43+'S-Detail'!S44 | E9: =B9+C9-D9 | G9: 0 | H9: ='S-Detail'!R42+'S-Detail'!R43+'S-Detail'!R44 | J9: =G9+H9-I9 | O9: =L9+M9-N9
B10: =B5+B6+B7+B8+B9 | C10: =C5+C6+C7+C8+C9 | D10: =D5+D6+D7+D8+D9 | E10: =E5+E6+E7+E8+E9 | F10: =F5+F6+F7+F8+F9 | G10: =G5+G6+G7+G8+G9 | H10: =H5+H6+H7+H8+H9 | I10: =I5+I6+I7+I8+I9 | ... O10: =O5+O6+O7+O8+O9
B11: CHIPS | G11: CANDIES | L11: WATER
A12: DAY | B12: BEGINNING INVENTORY | C12: TOTAL PURCHASE | D12: INVENTORY SOLD OUT | E12: ENDING INVENTORY | G12: BEGINNING INVENTORY | H12: TOTAL PURCHASE | I12: INVENTORY SOLD OUT | J12: ENDING INVENTORY | L12: BEGINNING INVENTORY | M12: TOTAL PURCHASE | N12: INVENTORY SOLD OUT | O12: ENDING INVENTORY
A13: 1 | E13: =B13+C13-D13 | J13: =G13+H13-I13 | O13: =L13+M13-N13
A14: 2 | E14: =B14+C14-D14 | J14: =G14+H14-I14 | O14: =L14+M14-N14
A15: 3 | E15: =B15+C15-D15 | J15: =G15+H15-I15 | O15: =L15+M15-N15
A16: 4 | E16: =B16+C16-D16 | J16: =G16+H16-I16 | O16: =L16+M16-N16
A17: 5 | E17: =B17+C17-D17 | J17: =G17+H17-I17 | O17: =L17+M17-N17
B18: =B13+B14+B15+B16+B17 | C18: =C13+C14+C15+C16+C17 | D18: =D13+D14+D15+D16+D17 | E18: =E13+E14+E15+E16+E17 | F18: =F13+F14+F15+F16+F17 | G18: =G13+G14+G15+G16+G17 | H18: =H13+H14+H15+H16+H17 | I18: =I13+I14+I15+I16+I17 | ... O18: =O13+O14+O15+O16+O17
B19: OAK FARMS | G19: ICE CREAM | L19: OTHERS
A20: DAY | B20: BEGINNING INVENTORY | C20: TOTAL PURCHASE | D20: INVENTORY SOLD OUT | E20: ENDING INVENTORY | G20: BEGINNING INVENTORY | H20: TOTAL PURCHASE | I20: INVENTORY SOLD OUT | J20: ENDING INVENTORY | L20: BEGINNING INVENTORY | M20: TOTAL PURCHASE | N20: INVENTORY SOLD OUT | O20: ENDING INVENTORY
A21: 1 | E21: =B21+C21-D21 | G21: 2 | J21: =G21+H21-I21 | O21: =L21+M21-N21
A22: 2 | E22: =B22+C22-D22 | J22: =G22+H22-I22 | O22: =L22+M22-N22
A23: 3 | E23: =B23+C23-D23 | J23: =G23+H23-I23 | O23: =L23+M23-N23
A24: 4 | E24: =B24+C24-D24 | J24: =G24+H24-I24 | O24: =L24+M24-N24
A25: 5 | E25: =B25+C25-D25 | J25: =G25+H25-I25 | O25: =L25+M25-N25
B26: =B21+B22+B23+B24+B25 | C26: =C21+C22+C23+C24+C25 | D26: =D21+D22+D23+D24+D25 | E26: =E21+E22+E23+E24+E25 | F26: =F21+F22+F23+F24+F25 | G26: =G21+G22+G23+G24+G25 | H26: =H21+H22+H23+H24+H25 | I26: =I21+I22+I23+I24+I25 | ... O26: =O21+O22+O23+O24+O25
A28: DAY | B28: BEGINNING INVENTORY | C28: TOTAL PURCHASE | D28: INVENTORY SOLD OUT | E28: ENDING INVENTORY | G28: BEGINNING INVENTORY | H28: TOTAL PURCHASE | I28: INVENTORY SOLD OUT | J28: ENDING INVENTORY | L28: BEGINNING INVENTORY | M28: TOTAL PURCHASE | N28: INVENTORY SOLD OUT | O28: ENDING INVENTORY
A29: 1 | E29: =B29+C29-D29 | J29: =G29+H29-I29 | L29: 7 | O29: =L29+M29-N29
A30: 2 | E30: =B30+C30-D30 | J30: =G30+H30-I30 | O30: =L30+M30-N30
A31: 3 | B31: 3 | E31: =B31+C31-D31 | G31: 2 | J31: =G31+H31-I31 | O31: =L31+M31-N31
A32: 4 | E32: =B32+C32-D32 | J32: =G32+H32-I32 | O32: =L32+M32-N32
A33: 5 | E33: =B33+C33-D33 | J33: =G33+H33-I33 | O33: =L33+M33-N33
B34: =B29+B30+B31+B32+B33 | C34: =C29+C30+C31+C32+C33 | D34: =D29+D30+D31+D32+D33 | E34: =E29+E30+E31+E32+E33 | F34: =F29+F30+F31+F32+F33 | G34: =G29+G30+G31+G32+G33 | H34: =H29+H30+H31+H32+H33 | I34: =I29+I30+I31+I32+I33 | ... O34: =O29+O30+O31+O32+O33
A36: DAY | B36: BEGINNING INVENTORY | C36: TOTAL PURCHASE | D36: INVENTORY SOLD OUT | E36: ENDING INVENTORY | G36: BEGINNING INVENTORY | H36: TOTAL PURCHASE | I36: INVENTORY SOLD OUT | J36: ENDING INVENTORY | L36: BEGINNING INVENTORY | M36: TOTAL PURCHASE | N36: INVENTORY SOLD OUT | O36: ENDING INVENTORY
A37: 1 | C37: 2 | E37: =B37+C37-D37 | H37: 1 | J37: =G37+H37-I37 | N37: 26 | O37: =L37+M37-N37
A38: 2 | E38: =B38+C38-D38 | G38: 2 | H38: 3 | J38: =G38+H38-I38 | N38: 44 | O38: =L38+M38-N38
A39: 3 | E39: =B39+C39-D39 | J39: =G39+H39-I39 | O39: =L39+M39-N39
A40: 4 | E40: =B40+C40-D40 | J40: =G40+H40-I40 | O40: =L40+M40-N40
A41: 5 | E41: =B41+C41-D41 | J41: =G41+H41-I41 | O41: =L41+M41-N41
B42: =B37+B38+B39+B40+B41 | C42: =C37+C38+C39+C40+C41 | D42: =D37+D38+D39+D40+D41 | E42: =E37+E38+E39+E40+E41 | F42: =F37+F38+F39+F40+F41 | G42: =G37+G38+G39+G40+G41 | H42: =H37+H38+H39+H40+H41 | I42: =I37+I38+I39+I40+I41 | ... O42: =O37+O38+O39+O40+O41
B44: =SUM(B5:B41) | C44: =SUM(C5:C41) | D44: =SUM(D5:D41) | E44: =SUM(E5:E41) | G44: =SUM(G5:G41) | H44: =SUM(H5:H41) | I44: =SUM(I5:I41) | J44: =SUM(J5:J41) | L44: =SUM(L5:L41) | M44: =SUM(M5:M41) | N44: =SUM(N5:N41) | O44: =SUM(O5:O41)
...

Sheet Ref Cells
A1: Number | B1: Day
A2: 1 | B2: Sunday
A3: 2 | B3: Monday
A4: 3 | B4: Tuesday
A5: 4 | B5: Wednesday
A6: 5 | B6: Thursday
A7: 6 | B7: Friday
A8: 7 | B8: Saturday

Sheet Sales (Auto)
A1: Date | B1: Employee 1 | C1: Employee 2 | D1: Employee 3 | E1: Employe 1 Sales | F1: Employe 2 Sales | G1: Employe 3 Sales | H1: Day | I1: Merchandise Sales | J1: Lotto Sales | K1: Gas Sales | L1: Amusement In | M1: Amusement Out | N1: Sales Tax In | O1: Sheet
A2: ='1'!$E$3 | B2: ='1'!$O$5 | C2: ='1'!$S$5 | D2: ='1'!$W$5 | E2: ='1'!$D$9 | F2: ='1'!$D$11 | G2: ='1'!$D$13 | H2: ='1'!$V$7 | I2: ='1'!$F$18 | J2: ='1'!$Z$30 | K2: ='1'!$F$30 | L2: ='1'!$F$34 | M2: ='1'!$F$35 | N2: ='1'!$F$17 | O2: 1
A3: ='2'!$E$3 | B3: ='2'!$O$5 | C3: ='2'!$S$5 | D3: ='2'!$W$5 | E3: ='2'!$D$9 | F3: ='2'!$D$11 | G3: ='2'!$D$13 | H3: ='2'!$V$7 | I3: ='2'!$F$18 | J3: ='2'!$Z$30 | K3: ='2'!$F$30 | L3: ='2'!$F$34 | M3: ='2'!$F$35 | N3: ='2'!$F$17 | O3: 2
A4: ='3'!$E$3 | B4: ='3'!$O$5 | C4: ='3'!$S$5 | D4: ='3'!$W$5 | E4: ='3'!$D$9 | F4: ='3'!$D$11 | G4: ='3'!$D$13 | H4: ='3'!$V$7 | I4: ='3'!$F$17 | J4: ='3'!$Z$29 | K4: ='3'!$F$29 | L4: ='3'!$F$33 | M4: ='3'!$F$34 | N4: ='3'!$F$16 | O4: 3
A5: ='4'!$E$3 | B5: ='4'!$O$5 | C5: ='4'!$S$5 | D5: ='4'!$W$5 | E5: ='4'!$D$9 | F5: ='4'!$D$11 | G5: ='4'!$D$13 | H5: ='4'!$V$7 | I5: ='4'!$F$17 | J5: ='4'!$Z$29 | K5: ='4'!$F$29 | L5: ='4'!$F$33 | M5: ='4'!$F$34 | N5: ='4'!$F$16 | O5: 4
A6: ='5'!$E$3 | B6: ='5'!$O$5 | C6: ='5'!$S$5 | D6: ='5'!$W$5 | E6: ='5'!$D$9 | F6: ='5'!$D$11 | G6: ='5'!$D$13 | H6: ='5'!$V$7 | I6: ='5'!$F$17 | J6: ='5'!$Z$29 | K6: ='5'!$F$29 | L6: ='5'!$F$33 | M6: ='5'!$F$34 | N6: ='5'!$F$16 | O6: 5
A7: ='6'!$E$3 | B7: ='6'!$O$5 | C7: ='6'!$S$5 | D7: ='6'!$W$5 | E7: ='6'!$D$9 | F7: ='6'!$D$11 | G7: ='6'!$D$13 | H7: ='6'!$V$7 | I7: ='6'!$F$17 | J7: ='6'!$Z$29 | K7: ='6'!$F$29 | L7: ='6'!$F$33 | M7: ='6'!$F$34 | N7: ='6'!$F$16 | O7: 6
A8: ='7'!$E$3 | B8: ='7'!$O$5 | C8: ='7'!$S$5 | D8: ='7'!$W$5 | E8: ='7'!$D$9 | F8: ='7'!$D$11 | G8: ='7'!$D$13 | H8: ='7'!$V$7 | I8: ='7'!$F$17 | J8: ='7'!$Z$29 | K8: ='7'!$F$29 | L8: ='7'!$F$33 | M8: ='7'!$F$34 | N8: ='7'!$F$16 | O8: 7
A9: ='8'!$E$3 | B9: ='8'!$O$5 | C9: ='8'!$S$5 | D9: ='8'!$W$5 | E9: ='8'!$D$9 | F9: ='8'!$D$11 | G9: ='8'!$D$13 | H9: ='8'!$V$7 | I9: ='8'!$F$17 | J9: ='8'!$Z$29 | K9: ='8'!$F$29 | L9: ='8'!$F$33 | M9: ='8'!$F$34 | N9: ='8'!$F$16 | O9: 8
A10: ='9'!$E$3 | B10: ='9'!$O$5 | C10: ='9'!$S$5 | D10: ='9'!$W$5 | E10: ='9'!$D$9 | F10: ='9'!$D$11 | G10: ='9'!$D$13 | H10: ='9'!$V$7 | I10: ='9'!$F$17 | J10: ='9'!$Z$29 | K10: ='9'!$F$29 | L10: ='9'!$F$33 | M10: ='9'!$F$34 | N10: ='9'!$F$16 | O10: 9
A11: ='10'!$E$3 | B11: ='10'!$O$5 | C11: ='10'!$S$5 | D11: ='10'!$W$5 | E11: ='10'!$D$9 | F11: ='10'!$D$11 | G11: ='10'!$D$13 | H11: ='10'!$V$7 | I11: ='10'!$F$17 | J11: ='10'!$Z$29 | K11: ='10'!$F$29 | L11: ='10'!$F$33 | M11: ='10'!$F$34 | N11: ='10'!$F$16 | O11: 10
A12: ='11'!$E$3 | B12: ='11'!$O$5 | C12: ='11'!$S$5 | D12: ='11'!$W$5 | E12: ='11'!$D$9 | F12: ='11'!$D$11 | G12: ='11'!$D$13 | H12: ='11'!$V$7 | I12: ='11'!$F$17 | J12: ='11'!$Z$29 | K12: ='11'!$F$29 | L12: ='11'!$F$33 | M12: ='11'!$F$34 | N12: ='11'!$F$16 | O12: 11
A13: ='12'!$E$3 | B13: ='12'!$O$5 | C13: ='12'!$S$5 | D13: ='12'!$W$5 | E13: ='12'!$D$9 | F13: ='12'!$D$11 | G13: ='12'!$D$13 | H13: ='12'!$V$7 | I13: ='12'!$F$17 | J13: ='12'!$Z$29 | K13: ='12'!$F$29 | L13: ='12'!$F$33 | M13: ='12'!$F$34 | N13: ='12'!$F$16 | O13: 12
A14: ='13'!$E$3 | B14: ='13'!$O$5 | C14: ='13'!$S$5 | D14: ='13'!$W$5 | E14: ='13'!$D$9 | F14: ='13'!$D$11 | G14: ='13'!$D$13 | H14: ='13'!$V$7 | I14: ='13'!$F$17 | J14: ='13'!$Z$29 | K14: ='13'!$F$29 | L14: ='13'!$F$33 | M14: ='13'!$F$34 | N14: ='13'!$F$16 | O14: 13
A15: ='14'!$E$3 | B15: ='14'!$O$5 | C15: ='14'!$S$5 | D15: ='14'!$W$5 | E15: ='14'!$D$9 | F15: ='14'!$D$11 | G15: ='14'!$D$13 | H15: ='14'!$V$7 | I15: ='14'!$F$17 | J15: ='14'!$Z$29 | K15: ='14'!$F$29 | L15: ='14'!$F$33 | M15: ='14'!$F$34 | N15: ='14'!$F$16 | O15: 14
A16: ='15'!$E$3 | B16: ='15'!$O$5 | C16: ='15'!$S$5 | D16: ='15'!$W$5 | E16: ='15'!$D$9 | F16: ='15'!$D$11 | G16: ='15'!$D$13 | H16: ='15'!$V$7 | I16: ='15'!$F$17 | J16: ='15'!$Z$29 | K16: ='15'!$F$29 | L16: ='15'!$F$33 | M16: ='15'!$F$34 | N16: ='15'!$F$16 | O16: 15
A17: ='16'!$E$3 | B17: ='16'!$O$5 | C17: ='16'!$S$5 | D17: ='16'!$W$5 | E17: ='16'!$D$9 | F17: ='16'!$D$11 | G17: ='16'!$D$13 | H17: ='16'!$V$7 | I17: ='16'!$F$17 | J17: ='16'!$Z$29 | K17: ='16'!$F$29 | L17: ='16'!$F$33 | M17: ='16'!$F$34 | N17: ='16'!$F$16 | O17: 16
A18: ='17'!$E$3 | B18: ='17'!$O$5 | C18: ='17'!$S$5 | D18: ='17'!$W$5 | E18: ='17'!$D$9 | F18: ='17'!$D$11 | G18: ='17'!$D$13 | H18: ='17'!$V$7 | I18: ='17'!$F$17 | J18: ='17'!$Z$29 | K18: ='17'!$F$29 | L18: ='17'!$F$33 | M18: ='17'!$F$34 | N18: ='17'!$F$16 | O18: 17
A19: ='18'!$E$3 | B19: ='18'!$O$5 | C19: ='18'!$S$5 | D19: ='18'!$W$5 | E19: ='18'!$D$9 | F19: ='18'!$D$11 | G19: ='18'!$D$13 | H19: ='18'!$V$7 | I19: ='18'!$F$17 | J19: ='18'!$Z$29 | K19: ='18'!$F$29 | L19: ='18'!$F$33 | M19: ='18'!$F$34 | N19: ='18'!$F$16 | O19: 18
A20: ='19'!$E$3 | B20: ='19'!$O$5 | C20: ='19'!$S$5 | D20: ='19'!$W$5 | E20: ='19'!$D$9 | F20: ='19'!$D$11 | G20: ='19'!$D$13 | H20: ='19'!$V$7 | I20: ='19'!$F$17 | J20: ='19'!$Z$29 | K20: ='19'!$F$29 | L20: ='19'!$F$33 | M20: ='19'!$F$34 | N20: ='19'!$F$16 | O20: 19
A21: ='20'!$E$3 | B21: ='20'!$O$5 | C21: ='20'!$S$5 | D21: ='20'!$W$5 | E21: ='20'!$D$9 | F21: ='20'!$D$11 | G21: ='20'!$D$13 | H21: ='20'!$V$7 | I21: ='20'!$F$17 | J21: ='20'!$Z$29 | K21: ='20'!$F$29 | L21: ='20'!$F$33 | M21: ='20'!$F$34 | N21: ='20'!$F$16 | O21: 20
A22: ='21'!$E$3 | B22: ='21'!$O$5 | C22: ='21'!$S$5 | D22: ='21'!$W$5 | E22: ='21'!$D$9 | F22: ='21'!$D$11 | G22: ='21'!$D$13 | H22: ='21'!$V$7 | I22: ='21'!$F$17 | J22: ='21'!$Z$29 | K22: ='21'!$F$29 | L22: ='21'!$F$33 | M22: ='21'!$F$34 | N22: ='21'!$F$16 | O22: 21
A23: ='22'!$E$3 | B23: ='22'!$O$5 | C23: ='22'!$S$5 | D23: ='22'!$W$5 | E23: ='22'!$D$9 | F23: ='22'!$D$11 | G23: ='22'!$D$13 | H23: ='22'!$V$7 | I23: ='22'!$F$17 | J23: ='22'!$Z$29 | K23: ='22'!$F$29 | L23: ='22'!$F$33 | M23: ='22'!$F$34 | N23: ='22'!$F$16 | O23: 22
A24: ='23'!$E$3 | B24: ='23'!$O$5 | C24: ='23'!$S$5 | D24: ='23'!$W$5 | E24: ='23'!$D$9 | F24: ='23'!$D$11 | G24: ='23'!$D$13 | H24: ='23'!$V$7 | I24: ='23'!$F$17 | J24: ='23'!$Z$29 | K24: ='23'!$F$29 | L24: ='23'!$F$33 | M24: ='23'!$F$34 | N24: ='23'!$F$16 | O24: 23
A25: ='24'!$E$3 | B25: ='24'!$O$5 | C25: ='24'!$S$5 | D25: ='24'!$W$5 | E25: ='24'!$D$9 | F25: ='24'!$D$11 | G25: ='24'!$D$13 | H25: ='24'!$V$7 | I25: ='24'!$F$17 | J25: ='24'!$Z$29 | K25: ='24'!$F$29 | L25: ='24'!$F$33 | M25: ='24'!$F$34 | N25: ='24'!$F$16 | O25: 24
A26: ='25'!$E$3 | B26: ='25'!$O$5 | C26: ='25'!$S$5 | D26: ='25'!$W$5 | E26: ='25'!$D$9 | F26: ='25'!$D$11 | G26: ='25'!$D$13 | H26: ='25'!$V$7 | I26: ='25'!$F$17 | J26: ='25'!$Z$29 | K26: ='25'!$F$29 | L26: ='25'!$F$33 | M26: ='25'!$F$34 | N26: ='25'!$F$16 | O26: 25
A27: ='26'!$E$3 | B27: ='26'!$O$5 | C27: ='26'!$S$5 | D27: ='26'!$W$5 | E27: ='26'!$D$9 | F27: ='26'!$D$11 | G27: ='26'!$D$13 | H27: ='26'!$V$7 | I27: ='26'!$F$17 | J27: ='26'!$Z$29 | K27: ='26'!$F$29 | L27: ='26'!$F$33 | M27: ='26'!$F$34 | N27: ='26'!$F$16 | O27: 26
A28: ='27'!$E$3 | B28: ='27'!$O$5 | C28: ='27'!$S$5 | D28: ='27'!$W$5 | E28: ='27'!$D$9 | F28: ='27'!$D$11 | G28: ='27'!$D$13 | H28: ='27'!$V$7 | I28: ='27'!$F$17 | J28: ='27'!$Z$29 | K28: ='27'!$F$29 | L28: ='27'!$F$33 | M28: ='27'!$F$34 | N28: ='27'!$F$16 | O28: 27
A29: ='28'!$E$3 | B29: ='28'!$O$5 | C29: ='28'!$S$5 | D29: ='28'!$W$5 | E29: ='28'!$D$9 | F29: ='28'!$D$11 | G29: ='28'!$D$13 | H29: ='28'!$V$7 | I29: ='28'!$F$17 | J29: ='28'!$Z$29 | K29: ='28'!$F$29 | L29: ='28'!$F$33 | M29: ='28'!$F$34 | N29: ='28'!$F$16 | O29: 28
A30: ='29'!$E$3 | B30: ='29'!$O$5 | C30: ='29'!$S$5 | D30: ='29'!$W$5 | E30: ='29'!$D$9 | F30: ='29'!$D$11 | G30: ='29'!$D$13 | H30: ='29'!$V$7 | I30: ='29'!$F$17 | J30: ='29'!$Z$29 | K30: ='29'!$F$29 | L30: ='29'!$F$33 | M30: ='29'!$F$34 | N30: ='29'!$F$16 | O30: 29
A31: ='30'!$E$3 | B31: ='30'!$O$5 | C31: ='30'!$S$5 | D31: ='30'!$W$5 | E31: ='30'!$D$9 | F31: ='30'!$D$11 | G31: ='30'!$D$13 | H31: ='30'!$V$7 | I31: ='30'!$F$17 | J31: ='30'!$Z$29 | K31: ='30'!$F$29 | L31: ='30'!$F$33 | M31: ='30'!$F$34 | N31: ='30'!$F$16 | O31: 30
A32: ='31'!$E$3 | B32: ='31'!$O$5 | C32: ='31'!$S$5 | D32: ='31'!$W$5 | E32: ='31'!$D$9 | F32: ='31'!$D$11 | G32: ='31'!$D$13 | H32: ='31'!$V$7 | I32: ='31'!$F$17 | J32: ='31'!$Z$29 | K32: ='31'!$F$29 | L32: ='31'!$F$33 | M32: ='31'!$F$34 | N32: ='31'!$F$16 | O32: 31

Sheet Sheet3
J6: =L7+'4'!J6:K6 | R6: =#REF!+'5'!R6:S6
J7: =F16+'4'!F42:G42 | R7: =#REF!+'5'!R7:S7
R8: =#REF!+'5'!R8:S8
R9: =#REF!+'5'!R9:S9
R10: =#REF!+'5'!R10:S10
R11: =#REF!+'5'!R11:S11
R12: =(R10-R11)+'5'!R12:S12
R13: =#REF!+'5'!R13:S13
R14: =#REF!+'5'!R14:S14
R15: =(128.55+29.42+665.77)/7++'5'!R15:S15
R16: =#REF!+'5'!R16:S16
F41: =H42+'4'!F41:G41

Sheet Purchases
A1: # | B1: Date | C1: Daily Expense: | D1: Expense Description | J1: Dollar Amount | M1: Expense Category | N1: Comment
A2: 1 | B2: 42987 | C2: 1 | D2: Lotto: | J2: 112 | M2: Do not Consider
A3: 2 | B3: 42987 | C3: 2 | D3: EBT | J3: 15.77 | M3: Do not Consider
A4: 3 | B4: 42987 | C4: 3 | D4: tax | J4: 150 | M4: Saving Benefit
A5: 4 | B5: 42987 | C5: 4 | D5: Gold Coin | J5: 1 | M5: Do not Consider
A6: 5 | B6: 42987 | C6: 5 | D6: help | J6: 22 | M6: Operating Expense
A7: 6 | B7: 42987 | C7: 6 | D7: Fahim | J7: 723 | M7: Employee Salaries
A8: 7 | B8: 42987 | C8: 7 | D8: Imtiaz | J8: 827 | M8: Employee Salaries
A9: 8 | B9: 42987 | C9: 8 | D9: Mustafa | J9: 165 | M9: Employee Salaries
A10: 9 | B10: 42987 | C10: 9 | D10: BS Gas | J10: 21.78 | M10: Management Benefit
A11: 10 | B11: 42987 | C11: 10 | D11: budweister | J11: 1000 | M11: Merchandise | N11: check 1044
A12: 11 | B12: 42987 | C12: 11 | D12: TX JASMINE | J12: 2000 | M12: Merchandise | N12: CHECK 1046
A13: 12 | B13: 42988 | C13: 1 | D13: Lotto: | J13: 112 | M13: Do not Consider
A14: 13 | C14: 2 | D14: help | J14: 16 | M14: Operating Expense
A15: 14 | C15: 3 | D15: tax | J15: 150 | M15: Saving Benefit
A16: 15 | C16: 4 | D16: imtious pay | J16: 311 | M16: Employee Salaries
A17: 16 | B17: 42989 | D17: PWI GAS | J17: 15000 | M17: PWI Gas Purchase
A18: 17 | D18: PWI GAS | J18: 3000 | M18: PWI Rent
A19: 18
A20: 19
A21: 20
A22: 21
A23: 22
A24: 23
A25: 24
A26: 25
A27: 26
A28: 27
A29: 28
A30: 29
... A300: 299

Sheet Expenses
A1: Expense Categories
A4: Merchandise
A5: Lotto EFT
A6: Employee Salaries
A7: Management Benefit
A8: PWI Gas Purchase
A9: PWI Rent
A10: Amusement Out
A11: Operating Expense
A12: Do not Consider
A13: Saving Benefit

Sheet Gas Report
A1: FUEL INVENTORY CONTROL REPORT
A3: FACILITY NAME: | C3: Sunmart 317 | H3: MONTH/YEAR: | I3: JANUARY | J3: 2020
A5: FACILITY ID #: | C5: 32218 | E5: TANK SIZE: | F5: 8000 | I5: FUEL TYPE: | J5: REGULAR
A7: DATE | B7: OPEN INVENTORY | D7: DELIVERY | E7: DAILY SALES | F7: BOOK INVENTORY | G7: CLOSING INVENTORY | I7: DAILY OVER/SHORT | J7: CUMULATIVE OVER/SHORT
B8: Inches | C8: Gallons | D8: Gallons | E8: Gallons | F8: Gallons | G8: Inches | H8: Gallons | I8: Gallons | J8: Gallons
A9: 1 | B9: ='1'!F23 | C9: ='1'!L47 | D9: ='1'!P47 | E9: ='1'!K42 | F9: =SUM(C9+D9-E9) | G9: ='1'!F24 | H9: ='1'!O42 | I9: =SUM(H9-F9) | J9: =I9
A10: 2 | B10: ='2'!F23 | C10: =H9 | D10: ='2'!P47 | E10: ='2'!K42 | F10: =SUM(C10+D10-E10) | G10: ='2'!F24 | H10: ='2'!O42 | I10: =SUM(H10-F10) | J10: =I10+J9
A11: 3 | B11: ='3'!F23 | C11: =H10 | D11: ='3'!P47 | E11: ='3'!K42 | F11: =SUM(C11+D11-E11) | G11: ='3'!F24 | H11: ='3'!O42 | I11: =SUM(H11-F11) | J11: =I11+J10
A12: 4 | B12: ='4'!F23 | C12: =H11 | D12: ='4'!P47 | E12: ='4'!K42 | F12: =SUM(C12+D12-E12) | G12: ='4'!F24 | H12: ='4'!O42 | I12: =SUM(H12-F12) | J12: =I12+J11
A13: 5 | B13: ='5'!F23 | C13: =H12 | D13: ='5'!P47 | E13: ='5'!K42 | F13: =SUM(C13+D13-E13) | G13: ='5'!F24 | H13: ='5'!O42 | I13: =SUM(H13-F13) | J13: =I13+J12
A14: 6 | B14: ='6'!F23 | C14: =H13 | D14: ='6'!P47 | E14: ='6'!K42 | F14: =SUM(C14+D14-E14) | G14: ='6'!F24 | H14: ='6'!O42 | I14: =SUM(H14-F14) | J14: =I14+J13
A15: 7 | B15: ='7'!F23 | C15: =H14 | D15: ='7'!P47 | E15: ='7'!K42 | F15: =SUM(C15+D15-E15) | G15: ='7'!F24 | H15: ='7'!O42 | I15: =SUM(H15-F15) | J15: =I15+J14
A16: 8 | B16: ='8'!F23 | C16: =H15 | D16: ='8'!P47 | E16: ='8'!K42 | F16: =SUM(C16+D16-E16) | G16: ='8'!F24 | H16: ='8'!O42 | I16: =SUM(H16-F16) | J16: =I16+J15
A17: 9 | B17: ='9'!F23 | C17: =H16 | D17: ='9'!P47 | E17: ='9'!K42 | F17: =SUM(C17+D17-E17) | G17: ='9'!F24 | H17: ='9'!O42 | I17: =SUM(H17-F17) | J17: =I17+J16
A18: 10 | B18: ='10'!F23 | C18: =H17 | D18: ='10'!P47 | E18: ='10'!K42 | F18: =SUM(C18+D18-E18) | G18: ='10'!F24 | H18: ='10'!O42 | I18: =SUM(H18-F18) | J18: =I18+J17
A19: 11 | B19: ='11'!F23 | C19: =H18 | D19: ='11'!P47 | E19: ='11'!K42 | F19: =SUM(C19+D19-E19) | G19: ='11'!F24 | H19: ='11'!O42 | I19: =SUM(H19-F19) | J19: =I19+J18
A20: 12 | B20: ='12'!F23 | C20: =H19 | D20: ='12'!P47 | E20: ='12'!K42 | F20: =SUM(C20+D20-E20) | G20: ='12'!F24 | H20: ='12'!O42 | I20: =SUM(H20-F20) | J20: =I20+J19
A21: 13 | B21: ='13'!F23 | C21: =H20 | D21: ='13'!P47 | E21: ='13'!K42 | F21: =SUM(C21+D21-E21) | G21: ='13'!F24 | H21: ='13'!O42 | I21: =SUM(H21-F21) | J21: =I21+J20
A22: 14 | B22: ='14'!F23 | C22: =H21 | D22: ='14'!P47 | E22: ='14'!K42 | F22: =SUM(C22+D22-E22) | G22: ='14'!F24 | H22: ='14'!O42 | I22: =SUM(H22-F22) | J22: =I22+J21
A23: 15 | B23: ='15'!F23 | C23: =H22 | D23: ='15'!P47 | E23: ='15'!K42 | F23: =SUM(C23+D23-E23) | G23: ='15'!F24 | H23: ='15'!O42 | I23: =SUM(H23-F23) | J23: =I23+J22
A24: 16 | B24: ='16'!F23 | C24: =H23 | D24: ='16'!P47 | E24: ='16'!K42 | F24: =SUM(C24+D24-E24) | G24: ='16'!F24 | H24: ='16'!O42 | I24: =SUM(H24-F24) | J24: =I24+J23
A25: 17 | B25: ='17'!F23 | C25: =H24 | D25: ='17'!P47 | E25: ='17'!K42 | F25: =SUM(C25+D25-E25) | G25: ='17'!F24 | H25: ='17'!O42 | I25: =SUM(H25-F25) | J25: =I25+J24
A26: 18 | B26: ='18'!F23 | C26: =H25 | D26: ='18'!P47 | E26: ='18'!K42 | F26: =SUM(C26+D26-E26) | G26: ='18'!F24 | H26: ='18'!O42 | I26: =SUM(H26-F26) | J26: =I26+J25
A27: 19 | B27: ='19'!F23 | C27: =H26 | D27: ='19'!P47 | E27: ='19'!K42 | F27: =SUM(C27+D27-E27) | G27: ='19'!F24 | H27: ='19'!O42 | I27: =SUM(H27-F27) | J27: =I27+J26
A28: 20 | B28: ='20'!F23 | C28: =H27 | D28: ='20'!P47 | E28: ='20'!K42 | F28: =SUM(C28+D28-E28) | G28: ='20'!F24 | H28: ='20'!O42 | I28: =SUM(H28-F28) | J28: =I28+J27
A29: 21 | B29: ='21'!F23 | C29: =H28 | D29: ='21'!P47 | E29: ='21'!K42 | F29: =SUM(C29+D29-E29) | G29: ='21'!F24 | H29: ='21'!O42 | I29: =SUM(H29-F29) | J29: =I29+J28
A30: 22 | B30: ='22'!F23 | C30: =H29 | D30: ='22'!P47 | E30: ='22'!K42 | F30: =SUM(C30+D30-E30) | G30: ='22'!F24 | H30: ='22'!O42 | I30: =SUM(H30-F30) | J30: =I30+J29
A31: 23 | B31: ='23'!F23 | C31: =H30 | D31: ='23'!P47 | E31: ='23'!K42 | F31: =SUM(C31+D31-E31) | G31: ='23'!F24 | H31: ='23'!O42 | I31: =SUM(H31-F31) | J31: =I31+J30
A32: 24 | B32: ='24'!F23 | C32: =H31 | D32: ='24'!P47 | E32: ='24'!K42 | F32: =SUM(C32+D32-E32) | G32: ='24'!F24 | H32: ='24'!O42 | I32: =SUM(H32-F32) | J32: =I32+J31
A33: 25 | B33: ='25'!F23 | C33: =H32 | D33: ='25'!P47 | E33: ='25'!K42 | F33: =SUM(C33+D33-E33) | G33: ='25'!F24 | H33: ='25'!O42 | I33: =SUM(H33-F33) | J33: =I33+J32
A34: 26 | B34: ='26'!F23 | C34: =H33 | D34: ='26'!P47 | E34: ='26'!K42 | F34: =SUM(C34+D34-E34) | G34: ='26'!F24 | H34: ='26'!O42 | I34: =SUM(H34-F34) | J34: =I34+J33
A35: 27 | B35: ='27'!F23 | C35: =H34 | D35: ='27'!P47 | E35: ='27'!K42 | F35: =SUM(C35+D35-E35) | G35: ='27'!F24 | H35: ='27'!O42 | I35: =SUM(H35-F35) | J35: =I35+J34
A36: 28 | B36: ='28'!F23 | C36: =H35 | D36: ='28'!P47 | E36: ='28'!K42 | F36: =SUM(C36+D36-E36) | G36: ='28'!F24 | H36: ='28'!O42 | I36: =SUM(H36-F36) | J36: =I36+J35
A37: 29 | B37: ='29'!F23 | C37: =H36 | D37: ='29'!P47 | E37: ='29'!K42 | F37: =SUM(C37+D37-E37) | G37: ='29'!F24 | H37: ='29'!O42 | I37: =SUM(H37-F37) | J37: =I37+J36
A38: 30 | B38: ='30'!F23 | C38: =H37 | D38: ='30'!P47 | E38: ='30'!K42 | F38: =SUM(C38+D38-E38) | G38: ='30'!F24 | H38: ='30'!O42 | I38: =SUM(H38-F38) | J38: =I38+J37
A39: 31 | B39: ='31'!F23 | C39: =H38 | D39: ='31'!P47 | E39: ='31'!K42 | F39: =SUM(C39+D39-E39) | G39: ='31'!F24 | H39: ='31'!O42 | I39: =SUM(H39-F39) | J39: =I39+J38
A41: TOTAL SALES: | C41: =SUM(E9:E39) | H41: TOTAL OVER/SHORT: | J41: =SUM(I9:I39)
A43: LEAK TEST: | C43: =SUM(C41*0.01)+(130) | E43: WATER CHECK (INCHES): | G43: 0 | I43: PASS / FAIL: | J43: =IF((SQRT(SUM(I9:I39)*SUM(I9:I39)))>C43,"FAIL","PASS")
A45: NOTE: Monthly over/short should not be greater than 1% plus 130 gallons for compliance with state regulations. Notify the TCEQ Regional Office within 24 hours if your over/short exceeds this amount.
A47: FUEL INVENTORY CONTROL REPORT
...

Sheet Month-End
A1: Montly Report
A2: Days | B2: Total Sale | C2: Taxable | D2: Total Tax | E2: Credit Card sales | F2: Total Lotto Sale | G2: Total Lotto Paid-Out | H2: Total Lotto Balance | I2: TotalGassolin Sale (Gallon) | J2: TotalGassolin Sale$ | K2: Daily Rent | L2: EBT
A3: 1 | B3: ='1'!L7 | C3: ='1'!F16 | D3: ='1'!F17 | E3: ='1'!L12 | F3: ='1'!Z30 | G3: ='1'!Z9 | H3: ='1'!F45-F46 | I3: ='1'!F31 | J3: ='1'!F15 | K3: =(128.55+29.42+665.77)/7 | L3: ='1'!Z10
A4: 2 | B4: ='2'!L7 | C4: ='2'!F16 | D4: ='2'!F17 | E4: ='2'!L12 | F4: ='2'!Z30 | G4: ='2'!Z9 | H4: ='2'!F45-F46 | I4: ='2'!F31 | J4: ='2'!F15 | K4: =(128.55+29.42+665.77)/7 | L4: ='2'!Z10
A5: 3 | B5: ='3'!L7 | C5: ='3'!F16 | D5: ='3'!F17 | E5: ='3'!L12 | F5: ='3'!Z30 | G5: ='3'!Z9 | H5: ='3'!F45-F46 | I5: ='3'!F31 | J5: ='3'!F15 | K5: =(128.55+29.42+665.77)/7 | L5: ='3'!Z10
A6: 4 | B6: ='4'!L7 | C6: ='4'!F16 | D6: ='4'!F17 | E6: ='4'!L12 | F6: ='4'!Z30 | G6: ='4'!Z9 | H6: ='4'!F45-F46 | I6: ='4'!F31 | J6: ='4'!F15 | K6: =(128.55+29.42+665.77)/7 | L6: ='4'!Z10
A7: 5 | B7: ='5'!L7 | C7: ='5'!F16 | D7: ='5'!F17 | E7: ='5'!L12 | F7: ='5'!Z30 | G7: ='5'!Z9 | H7: ='5'!F45-F46 | I7: ='5'!F31 | J7: ='5'!F15 | K7: =(128.55+29.42+665.77)/7 | L7: ='5'!Z10
A8: 6 | B8: ='6'!L7 | C8: ='6'!F16 | D8: ='6'!F17 | E8: ='6'!L12 | F8: ='6'!Z30 | G8: ='6'!Z9 | H8: ='6'!F45-F46 | I8: ='6'!F31 | J8: ='6'!F15 | K8: =(128.55+29.42+665.77)/7 | L8: ='6'!Z10
A9: 7 | B9: ='7'!L7 | C9: ='7'!F16 | D9: ='7'!F17 | E9: ='7'!L12 | F9: ='7'!Z30 | G9: ='7'!Z9 | H9: ='7'!F45-F46 | I9: ='7'!F31 | J9: ='7'!F15 | K9: =(128.55+29.42+665.77)/7 | L9: ='7'!Z10
A10: 8 | B10: ='8'!L7 | C10: ='8'!F16 | D10: ='8'!F17 | E10: ='8'!L12 | F10: ='8'!Z30 | G10: ='8'!Z9 | H10: ='8'!F45-F46 | I10: ='8'!F31 | J10: ='8'!F15 | K10: =(128.55+29.42+665.77)/7 | L10: ='8'!Z10
A11: 9 | B11: ='9'!L7 | C11: ='9'!F16 | D11: ='9'!F17 | E11: ='9'!L12 | F11: ='9'!Z30 | G11: ='9'!Z9 | H11: ='9'!F45-F46 | I11: ='9'!F31 | J11: ='9'!F15 | K11: =(128.55+29.42+665.77)/7 | L11: ='9'!Z10
A12: 10 | B12: ='10'!L7 | C12: ='10'!F16 | D12: ='10'!F17 | E12: ='10'!L12 | F12: ='10'!Z30 | G12: ='10'!Z9 | H12: ='10'!F45-F46 | I12: ='10'!F31 | J12: ='10'!F15 | K12: =(128.55+29.42+665.77)/7 | L12: ='10'!Z10
A13: 11 | B13: ='11'!L7 | C13: ='11'!F16 | D13: ='11'!F17 | E13: ='11'!L12 | F13: ='11'!Z30 | G13: ='11'!Z9 | H13: ='11'!F45-F46 | I13: ='11'!F31 | J13: ='11'!F15 | K13: =(128.55+29.42+665.77)/7 | L13: ='11'!Z10
A14: 12 | B14: ='12'!L7 | C14: ='12'!F16 | D14: ='12'!F17 | E14: ='12'!L12 | F14: ='12'!Z30 | G14: ='12'!Z9 | H14: ='12'!F45-F46 | I14: ='12'!F31 | J14: ='12'!F15 | K14: =(128.55+29.42+665.77)/7 | L14: ='12'!Z10
A15: 13 | B15: ='13'!L7 | C15: ='13'!F16 | D15: ='13'!F17 | E15: ='13'!L12 | F15: ='13'!Z30 | G15: ='13'!Z9 | H15: ='13'!F45-F46 | I15: ='13'!F31 | J15: ='13'!F15 | K15: =(128.55+29.42+665.77)/7 | L15: ='13'!Z10
A16: 14 | B16: ='14'!L7 | C16: ='14'!F16 | D16: ='14'!F17 | E16: ='14'!L12 | F16: ='14'!Z30 | G16: ='14'!Z9 | H16: ='14'!F45-F46 | I16: ='14'!F31 | J16: ='14'!F15 | K16: =(128.55+29.42+665.77)/7 | L16: ='14'!Z10
A17: 15 | B17: ='15'!L7 | C17: ='15'!F16 | D17: ='15'!F17 | E17: ='15'!L12 | F17: ='15'!Z30 | G17: ='15'!Z9 | H17: ='15'!F45-F46 | I17: ='15'!F31 | J17: ='15'!F15 | K17: =(128.55+29.42+665.77)/7 | L17: ='15'!Z10
A18: 16 | B18: ='16'!L7 | C18: ='16'!F16 | D18: ='16'!F17 | E18: ='16'!L12 | F18: ='16'!Z30 | G18: ='16'!Z9 | H18: ='16'!F45-F46 | I18: ='16'!F31 | J18: ='16'!F15 | K18: =(128.55+29.42+665.77)/7 | L18: ='16'!Z10
A19: 17 | B19: ='17'!L7 | C19: ='17'!F16 | D19: ='17'!F17 | E19: ='17'!L12 | F19: ='17'!Z30 | G19: ='17'!Z9 | H19: ='17'!F45-F46 | I19: ='17'!F31 | J19: ='17'!F15 | K19: =(128.55+29.42+665.77)/7 | L19: ='17'!Z10
A20: 18 | B20: ='18'!L7 | C20: ='18'!F16 | D20: ='18'!F17 | E20: ='18'!L12 | F20: ='18'!Z30 | G20: ='18'!Z9 | H20: ='18'!F45-F46 | I20: ='18'!F31 | J20: ='18'!F15 | K20: =(128.55+29.42+665.77)/7 | L20: ='18'!Z10
A21: 19 | B21: ='19'!L7 | C21: ='19'!F16 | D21: ='19'!F17 | E21: ='19'!L12 | F21: ='19'!Z30 | G21: ='19'!Z9 | H21: ='19'!F45-F46 | I21: ='19'!F31 | J21: ='19'!F15 | K21: =(128.55+29.42+665.77)/7 | L21: ='19'!Z10
A22: 20 | B22: ='20'!L7 | C22: ='20'!F16 | D22: ='20'!F17 | E22: ='20'!L12 | F22: ='20'!Z30 | G22: ='20'!Z9 | H22: ='20'!F45-F46 | I22: ='20'!F31 | J22: ='20'!F15 | K22: =(128.55+29.42+665.77)/7 | L22: ='20'!Z10
A23: 21 | B23: ='21'!L7 | C23: ='21'!F16 | D23: ='21'!F17 | E23: ='21'!L12 | F23: ='21'!Z30 | G23: ='21'!Z9 | H23: ='21'!F45-F46 | I23: ='21'!F31 | J23: ='21'!F15 | K23: =(128.55+29.42+665.77)/7 | L23: ='21'!Z10
A24: 22 | B24: ='22'!L7 | C24: ='22'!F16 | D24: ='22'!F17 | E24: ='22'!L12 | F24: ='22'!Z30 | G24: ='22'!Z9 | H24: ='22'!F45-F46 | I24: ='22'!F31 | J24: ='22'!F15 | K24: =(128.55+29.42+665.77)/7 | L24: ='22'!Z10
A25: 23 | B25: ='23'!L7 | C25: ='23'!F16 | D25: ='23'!F17 | E25: ='23'!L12 | F25: ='23'!Z30 | G25: ='23'!Z9 | H25: ='23'!F45-F46 | I25: ='23'!F31 | J25: ='23'!F15 | K25: =(128.55+29.42+665.77)/7 | L25: ='23'!Z10
A26: 24 | B26: ='24'!L7 | C26: ='24'!F16 | D26: ='24'!F17 | E26: ='24'!L12 | F26: ='24'!Z30 | G26: ='24'!Z9 | H26: ='24'!F45-F46 | I26: ='24'!F31 | J26: ='24'!F15 | K26: =(128.55+29.42+665.77)/7 | L26: ='24'!Z10
A27: 25 | B27: ='25'!L7 | C27: ='25'!F16 | D27: ='25'!F17 | E27: ='25'!L12 | F27: ='25'!Z30 | G27: ='25'!Z9 | H27: ='25'!F45-F46 | I27: ='25'!F31 | J27: ='25'!F15 | K27: =(128.55+29.42+665.77)/7 | L27: ='25'!Z10
A28: 26 | B28: ='26'!L7 | C28: ='26'!F16 | D28: ='26'!F17 | E28: ='26'!L12 | F28: ='26'!Z30 | G28: ='26'!Z9 | H28: ='26'!F45-F46 | I28: ='26'!F31 | J28: ='26'!F15 | K28: =(128.55+29.42+665.77)/7 | L28: ='26'!Z10
A29: 27 | B29: ='27'!L7 | C29: ='27'!F16 | D29: ='27'!F17 | E29: ='27'!L12 | F29: ='27'!Z30 | G29: ='27'!Z9 | H29: ='27'!F45-F46 | I29: ='27'!F31 | J29: ='27'!F15 | K29: =(128.55+29.42+665.77)/7 | L29: ='27'!Z10
A30: 28 | B30: ='28'!L7 | C30: ='28'!F16 | D30: ='28'!F17 | E30: ='28'!L12 | F30: ='28'!Z30 | G30: ='28'!Z9 | H30: ='28'!F45-F46 | I30: ='28'!F31 | J30: ='28'!F15 | K30: =(128.55+29.42+665.77)/7 | L30: ='28'!Z10
A31: 29 | B31: ='29'!L7 | C31: ='29'!F16 | D31: ='29'!F17 | E31: ='29'!L12 | F31: ='29'!Z30 | G31: ='29'!Z9 | H31: ='29'!F45-F46 | I31: ='29'!F31 | J31: ='29'!F15 | K31: =(128.55+29.42+665.77)/7 | L31: ='29'!Z10
A32: 30 | B32: ='30'!L7 | C32: ='30'!F16 | D32: ='30'!F17 | E32: ='30'!L12 | F32: ='30'!Z30 | G32: ='30'!Z9 | H32: ='30'!F45-F46 | I32: ='30'!F31 | J32: ='30'!F15 | K32: =(128.55+29.42+665.77)/7 | L32: ='30'!Z10
A33: 31 | B33: ='31'!L7 | C33: ='31'!F16 | D33: ='31'!F17 | E33: ='31'!L12 | F33: ='31'!Z30 | G33: ='31'!Z9 | H33: ='31'!F45-F46 | I33: ='31'!F31 | J33: ='31'!F15 | K33: =(128.55+29.42+665.77)/7 | L33: ='31'!Z10
A34: Total | B34: =SUM(B3:B33) | C34: =SUM(C3:C33) | D34: =SUM(D3:D33) | E34: =SUM(E3:E33) | F34: =SUM(F3:F33) | G34: =SUM(G3:G33) | H34: =SUM(H3:H33) | I34: =SUM(I3:I33) | ... L34: =SUM(L3:L33)

Sheet 1
G1: Woodbridge Mini Mart
C3: Date: | E3: 45658
C5: Register 01 | L5: Employee: | O5: Salim | S5: Aziz | W5: Krishna
C6: Phone Card: | F6: 0 | H6: Lottery Register Report: | L6: 0 | S6: Date: | V6: =E3
C7: Lotto: | F7: =Z30 | H7: Net Sales: | L7: 0 | S7: Day: | V7: =VLOOKUP(WEEKDAY(E3),'Ref Cells'!$A:$B,2,0) | Z7: 0.29166667
C8: Gas Gal.: | F8: =SUM(E27:H27) | H8: Lotto Diff: | L8: =Z30-L6 | S8: Daily Expense:
C9: M: | D9: 0 | F9: Emp: | G9: =O5 | H9: Gas Diff: | L9: 0 | S9: 1 | T9: Lotto: | Z9: 0
